Workbook
Name Interventions: ='07_Domains'!$A$3:$A$37
Name Donors: ='07_Domains'!$B$3:$B$31
Name Projects: ='07_Domains'!$C$3:$C$26
Name Regions: ='07_Domains'!$D$3:$D$31
Name Statuses: ='07_Domains'!$E$3:$E$36
Name All_Provinces: ='07_Domains'!$F$3:$F$57
Name All_Districts: ='07_Domains'!$G$3:$G$371
Name AwardGroups: ='07_Domains'!$H$3:$H$25
Name Families: ='07_Domains'!$I$3:$I$28
Name Contractors: ='07_Domains'!$J$3:$J$136

Sheet 00_How_to_Use
B1: Construction Works Scheme Tracker
B2: Emergency Food Security Project (EFSP) · Component 2: Water and Resilience Services · WBK/AF-2 · How to use and how to add or remove columns and domains
B5: What this workbook does
B6: Purpose | C6: Track every construction scheme from design through handover. Each scheme is one row. Each pipeline step has its own date. Excel then calculates how many days it took to move from one step to the next, how long the scheme has sat in the current step, and the total days from the first date to the last.
B7: Sheets | C7: 01_Scheme_Tracker is the working register (one row per sub-project). 02_Dashboard summarises counts and average durations. 03_Package_Summary rolls every contract package to one row (Package #8 and #10 sit here as single packages). 10_By_Contractor lists each company once, with how many unique contracts it holds (Zahid Saeed / ZSCC is one awarded contract covering four canals). 11_Package_Status counts unique packages in each pipeline step and shows how each status is shared across Watershed Management, Irrigation Scheme, Drip Irrigation, LLL, and Agroforestry. 04_Date_Rules explains how each date is used and how schedule health is coloured. 05_Example_Filled shows two worked examples so you can see the day-count formulas. 06_Status_Pipeline is the ordered list of steps. 07_Domains holds dropdown lists (major intervention, sub-type, donor, project, region, Awarded / Not awarded). 08_Geography holds province and district lists. 09_Lookups maps region/province names to those lists.
B9: Daily use
B10: Add a scheme | C10: Go to 01_Scheme_Tracker and type in the next empty row. Choose Major intervention first (Watershed Management, Irrigation Scheme, Drip Irrigation, Agroforestry saplings / seeds, or Laser Land Leveler), then Intervention sub-type (protection wall, irrigation canal, check dam, and so on). Dropdowns are also attached for Project, Region, Province, District, Donor, Awarded / Not awarded, and Reported Status. | D10: 01_Scheme_Tracker
B11: Packages that cover several sites | C11: One Package / Contract Name can cover several canals or check dams in different districts. Keep one row per sub-project (location) so province, district, village, and progress stay honest. Give every row of that contract the same Package ID and the same Package / Contract Name. Sub-project in package shows 1 of 4, 2 of 4, … Example: Package #8-AF2 IS (Khas Kunar Lower canal + Bahrabad canal) is two rows, one Package ID. Package #10-AF2 IS (Baraki, Darbal, Nawikhar, Mangali) is four rows, one Package ID. On the tracker, extra rows of the same package are grouped — use the outline +/- at the left margin to collapse them. 03_Package_Summary lists each package once. | D11: 01_Scheme_Tracker / 03_Package_Summary
B12: Find contracts awarded to one company | C12: The contractor name is repeated on every sub-project of that contract. Filtering Contractor Name on 01_Scheme_Tracker for 'Zahid Saeed Engineering and Construction Company (ZSCC)' shows four rows — those are four canals on the same Package #10 contract (057/2025), not four contracts. To see unique contracts: open 10_By_Contractor and filter the company (ZSCC = 1 awarded contract, 4 sub-projects), or open 03_Package_Summary and filter Contractor Name. Count Package IDs / Contract Numbers, not the number of tracker rows. | D12: 10_By_Contractor / 03_Package_Summary
B13: How many packages are in each status | C13: 02_Dashboard counts sub-projects. That overstates a step when one contract has many sites (50 LLL units and 39 agroforestry rows are each one package still Under Awarding). Open 11_Package_Status for unique-package counts: Under Design, Under Review of WRI, Under LTO Review, PR to be Raised, ITB Launched, Retendered, Technical Evaluation, Under Awarding, Awarded, Under Construction, Completed. A package takes the least-advanced status of its unfinished sites. It is Completed only when every sub-project is completed. Filter Package status on 03_Package_Summary to list them. | D13: 11_Package_Status
B14: Enter status dates | C14: When a scheme reaches a step, type that day's date in the matching 'Date:' column (for example Date: Under Design, Date: ITB Launched). Use a real date, not text. Current Status then switches automatically to the latest dated step. If no dates are entered yet, Current Status falls back to Reported Status. | D14: Section 4 of the tracker
B15: Awarded date and contract duration | C15: Type the contract-signature (or notice of award) date in the Date: Awarded column in section 4. The Awarded Date field in section 2 copies it automatically. Contract Duration (months) is the period in the contract. Planned End Date is calculated with EDATE(Awarded Date, duration). Physical Works Progress % is 0–100. Contractor Name and Contract Number are free text. | D15: Sections 2 and 4 of the tracker
B16: Reading the day counts | C16: Each 'Days … → …' column is the number of days from the previous filled date to this step's date. If a step is skipped, the count still uses the last previous date that was filled. 'Days in current status' is TODAY minus the latest status date (this number changes every day). 'Total days first → last step' is last filled date minus first filled date. 'Days over target this step' is days in current status minus the target days set on 06_Status_Pipeline (blank if there is no target). | D16: Sections 3 and 5
B17: Schedule health colours | C17: Schedule health is calculated from planned dates and TODAY() — it changes every calendar day. GREEN — On track, or completed. AMBER — At risk / close to off track: the planned award or contract end is within 30 days. RED — Behind: today is after the expected award date (Not awarded) or after the contract end date (Awarded), or physical progress is more than 15 percentage points behind the share of the contract period that has already elapsed. 'Days vs planned date' is days remaining (positive) or days overdue (negative). Full rules, including which date each condition uses, are on 04_Date_Rules. | D17: 04_Date_Rules
B18: What a status date means | C18: Type the calendar day the scheme reached that step (the day the step started or was achieved), not a forecast. Leave later steps blank until they happen. Current Status is the latest dated step. If no dates are entered yet, Current Status uses Reported Status. Awarded Date copies Date: Awarded. Planned End Date uses the contract end if you typed one, otherwise EDATE(Awarded Date, duration months). Not awarded rows are judged against Expected award date (and, if that is blank, the expected end). Awarded rows are judged against the planned / contract end and against physical progress over elapsed time. | D18: 04_Date_Rules
B20: Add or remove domains (dropdown values)
B21: Add an intervention type, donor, project, or region | C21: Open 07_Domains. Type the new value in the first empty cell at the bottom of that column. Do not leave a blank row in the middle of the list. The dropdowns expand automatically (named ranges use COUNTA). You do not need to re-run the generator for this. | D21: 07_Domains
B22: Remove a domain value | C22: Delete the cell on 07_Domains (or 08_Geography). Existing scheme rows that already use that value keep showing it; new rows will no longer offer it in the dropdown. | D22: 07_Domains / 08_Geography
B23: Add a province | C23: 1) On 08_Geography, under the correct region code column in the province block, type the province name. 2) Add a new district column for that province in the district block (copy an adjacent column). 3) On 09_Lookups, add a row: Province name | Dist_<Province> named range. 4) Define the named range Dist_<Province> (Formulas → Name Manager) pointing at the district cells. The reliable alternative is to add the province in tracker_config.py GEOGRAPHY and run generate_tracker.py. | D23: 08_Geography + 09_Lookups
B24: Add a district | C24: On 08_Geography find the province column in the district block and type the district in the next empty cell. The Dist_ named range grows automatically. No other change is required. | D24: 08_Geography
B26: Add or remove status steps (the tracking pipeline)
B27: Add a step at the end (no script) | C27: Open 06_Status_Pipeline. Spare slots are already reserved at the bottom. Type the new status name, a short name, a description, and optional target days in the first spare row. The matching Date column header on 01_Scheme_Tracker updates itself. Start entering dates in that column. Duration headers also pick up the new name. | D27: 06_Status_Pipeline spare slots
B28: Add a step in the middle, or remove a step | C28: Changing order affects rows that already have dates, because dates sit in fixed columns. Preferred method: edit STATUS_PIPELINE in tracker_config.py (add, remove, or reorder dicts) and run python3 generate_tracker.py. That rebuilds date columns, duration formulas, dropdowns, and the dashboard. Copy any dates you already typed into a backup first — regenerating replaces the workbook file. | D28: tracker_config.py
B29: Hide a column you do not need | C29: On 01_Scheme_Tracker, select the column → right-click → Hide. Do not delete formula columns (sections 3 and 5) or the tracker will break. Hidden columns can be unhidden later. | D29: 01_Scheme_Tracker
B30: Add an extra data column (GPS, engineer, photo link, …) | C30: Insert a column inside section 1 (identity) or section 2 (contract), not inside the date or duration blocks. Give it a header in row 3. Filters will include it after you re-apply AutoFilter if needed. To make it permanent in future rebuilds, append a tuple to IDENTITY_COLUMNS or CONTRACT_COLUMNS in tracker_config.py. | D30: 01_Scheme_Tracker / tracker_config.py
B32: Rules that keep the numbers honest
B33: Dates must move forward | C33: A later step should not have an earlier date than a previous step. Negative day-counts mean the dates need checking.
B34: One row = one sub-project; one Package ID = one contract | C34: If a package has three check dams or four canals, use three or four rows. Do not merge those rows — AutoFilter and sort would break. Repeat the Package / Contract Name and Package ID on every row. Cost may be per sub-project (as in the master file) or only on the first row. | D34: 03_Package_Summary
B35: Grey cells are formulas | C35: Do not type over Current Status, Planned End Date, day-count columns, or helper columns. White cells are inputs.
B36: DEMO rows | C36: 05_Example_Filled is for learning. Do not copy those dates into official reports. | D36: 05_Example_Filled
B38: Status pipeline (default)
B39: Step | C39: Status | D39: What it means | E39: Target days
B40: 1 | C40: Under Design | D40: Detailed design, surveys, and drawings are being prepared. | E40: 30
B41: 2 | C41: Under Review of WRI | D41: Water Resources / WRI is reviewing the design package. | E41: 14
B42: 3 | C42: Under LTO Review | D42: Legal / LTO clearance of the package. | E42: 10
B43: 4 | C43: PR to be Raised | D43: Purchase request / procurement request still to be raised. | E43: 10
B44: 5 | C44: ITB Launched | D44: Invitation to Bid has been issued. | E44: 21
B45: 6 | C45: Retendered (Re-ITB) | D45: Previous bid failed or was cancelled; invitation re-issued. | E45: 21
B46: 7 | C46: Under Technical Evaluation | D46: Bids are under technical evaluation. | E46: 14
B47: 8 | C47: Under Awarding | D47: Award recommendation, negotiations, and approval. | E47: 14
...

Sheet 01_Scheme_Tracker
A1: Construction Works Scheme Tracker · live register — type dates in section 4
A2: 1. Scheme identity | Q2: 2. Contract and physical progress | AC2: 3. Live status and schedule health (calculated) | AI2: 4. Status dates — enter the date each step was reached | AW2: 5. Days between steps (calculated)
A3: SN | B3: Package ID | C3: Package / Contract Name | D3: Sub-project in package | E3: Scheme ID | F3: Sub-project / scheme name | G3: Major intervention | H3: Intervention sub-type | I3: Project Name | J3: Region | K3: Province | L3: District | M3: Village | N3: Donor | O3: Awarded / Not awarded | P3: Source sheet | Q3: Contractor Name | R3: Contract Number | S3: Contract Cost (USD) | T3: Awarded Date | U3: Expected award date | V3: Contract Duration (months) | W3: Contract / expected end date | X3: Planned End Date | Y3: Actual completion date | Z3: Physical Works Progress % | AA3: Reported Status | AB3: Remarks | AC3: Current Status (auto) | AD3: Days in current status | AE3: Total days first → last step | AF3: Days over target this step | AG3: Schedule health | AH3: Days vs planned date | AI3: IF('06_Status_Pipeline'!B3="","(spare slot 1)","Date: "&'06_Status_Pipeline'!B3) | AJ3: IF('06_Status_Pipeline'!B4="","(spare slot 2)","Date: "&'06_Status_Pipeline'!B4) | AK3: IF('06_Status_Pipeline'!B5="","(spare slot 3)","Date: "&'06_Status_Pipeline'!B5) | AL3: IF('06_Status_Pipeline'!B6="","(spare slot 4)","Date: "&'06_Status_Pipeline'!B6) | AM3: IF('06_Status_Pipeline'!B7="","(spare slot 5)","Date: "&'06_Status_Pipeline'!B7) | AN3: IF('06_Status_Pipeline'!B8="","(spare slot 6)","Date: "&'06_Status_Pipeline'!B8) | AO3: IF('06_Status_Pipeline'!B9="","(spare slot 7)","Date: "&'06_Status_Pipeline'!B9) | AP3: IF('06_Status_Pipeline'!B10="","(spare slot 8)","Date: "&'06_Status_Pipeline'!B10) | AQ3: IF('06_Status_Pipeline'!B11="","(spare slot 9)","Date: "&'06_Status_Pipeline'!B11) | AR3: IF('06_Status_Pipeline'!B12="","(spare slot 10)","Date: "&'06_Status_Pipeline'!B12) | AS3: IF('06_Status_Pipeline'!B13="","(spare slot 11)","Date: "&'06_Status_Pipeline'!B13) | AT3: IF('06_Status_Pipeline'!B14="","(spare slot 12)","Date: "&'06_Status_Pipeline'!B14) | AU3: IF('06_Status_Pipeline'!B15="","(spare slot 13)","Date: "&'06_Status_Pipeline'!B15) | AV3: IF('06_Status_Pipeline'!B16="","(spare slot 14)","Date: "&'06_Status_Pipeline'!B16) | AW3: IF(AND('06_Status_Pipeline'!B3="",'06_Status_Pipeline'!B4=""),"(spare)","Days: "&IF('06_Status_Pipeline'!B3="","(prev)",'06_Status_Pipeline'!B3)&" → "&IF('06_Status_Pipeline'!B4="","(next)",'06_Status_Pipeline'!B4)) | AX3: IF(AND('06_Status_Pipeline'!B4="",'06_Status_Pipeline'!B5=""),"(spare)","Days: "&IF('06_Status_Pipeline'!B4="","(prev)",'06_Status_Pipeline'!B4)&" → "&IF('06_Status_Pipeline'!B5="","(next)",'06_Status_Pipeline'!B5)) | AY3: IF(AND('06_Status_Pipeline'!B5="",'06_Status_Pipeline'!B6=""),"(spare)","Days: "&IF('06_Status_Pipeline'!B5="","(prev)",'06_Status_Pipeline'!B5)&" → "&IF('06_Status_Pipeline'!B6="","(next)",'06_Status_Pipeline'!B6)) | AZ3: IF(AND('06_Status_Pipeline'!B6="",'06_Status_Pipeline'!B7=""),"(spare)","Days: "&IF('06_Status_Pipeline'!B6="","(prev)",'06_Status_Pipeline'!B6)&" → "&IF('06_Status_Pipeline'!B7="","(next)",'06_Status_Pipeline'!B7)) | BA3: IF(AND('06_Status_Pipeline'!B7="",'06_Status_Pipeline'!B8=""),"(spare)","Days: "&IF('06_Status_Pipeline'!B7="","(prev)",'06_Status_Pipeline'!B7)&" → "&IF('06_Status_Pipeline'!B8="","(next)",'06_Status_Pipeline'!B8)) | BB3: IF(AND('06_Status_Pipeline'!B8="",'06_Status_Pipeline'!B9=""),"(spare)","Days: "&IF('06_Status_Pipeline'!B8="","(prev)",'06_Status_Pipeline'!B8)&" → "&IF('06_Status_Pipeline'!B9="","(next)",'06_Status_Pipeline'!B9)) | BC3: IF(AND('06_Status_Pipeline'!B9="",'06_Status_Pipeline'!B10=""),"(spare)","Days: "&IF('06_Status_Pipeline'!B9="","(prev)",'06_Status_Pipeline'!B9)&" → "&IF('06_Status_Pipeline'!B10="","(next)",'06_Status_Pipeline'!B10)) | BD3: IF(AND('06_Status_Pipeline'!B10="",'06_Status_Pipeline'!B11=""),"(spare)","Days: "&IF('06_Status_Pipeline'!B10="","(prev)",'06_Status_Pipeline'!B10)&" → "&IF('06_Status_Pipeline'!B11="","(next)",'06_Status_Pipeline'!B11)) | BE3: IF(AND('06_Status_Pipeline'!B11="",'06_Status_Pipeline'!B12=""),"(spare)","Days: "&IF('06_Status_Pipeline'!B11="","(prev)",'06_Status_Pipeline'!B11)&" → "&IF('06_Status_Pipeline'!B12="","(next)",'06_Status_Pipeline'!B12)) | BF3: IF(AND('06_Status_Pipeline'!B12="",'06_Status_Pipeline'!B13=""),"(spare)","Days: "&IF('06_Status_Pipeline'!B12="","(prev)",'06_Status_Pipeline'!B12)&" → "&IF('06_Status_Pipeline'!B13="","(next)",'06_Status_Pipeline'!B13)) | BG3: IF(AND('06_Status_Pipeline'!B13="",'06_Status_Pipeline'!B14=""),"(spare)","Days: "&IF('06_Status_Pipeline'!B13="","(prev)",'06_Status_Pipeline'!B13)&" → "&IF('06_Status_Pipeline'!B14="","(next)",'06_Status_Pipeline'!B14)) | BH3: IF(AND('06_Status_Pipeline'!B14="",'06_Status_Pipeline'!B15=""),"(spare)","Days: "&IF('06_Status_Pipeline'!B14="","(prev)",'06_Status_Pipeline'!B14)&" → "&IF('06_Status_Pipeline'!B15="","(next)",'06_Status_Pipeline'!B15)) | BI3: IF(AND('06_Status_Pipeline'!B15="",'06_Status_Pipeline'!B16=""),"(spare)","Days: "&IF('06_Status_Pipeline'!B15="","(prev)",'06_Status_Pipeline'!B15)&" → "&IF('06_Status_Pipeline'!B16="","(next)",'06_Status_Pipeline'!B16)) | BJ3: _ProvinceList | BK3: _DistrictList
A4: IF(F4="","",ROW()-3) | B4: AF2-AGF-ALL | C4: Agroforestry saplings and seeds 2026/27 | D4: 1 of 39 | E4: AF2-AGF-N-001 | F4: Agroforestry — Badakhshan / Wardoj | G4: Agroforestry saplings / seeds | H4: Saplings and seeds | I4: Emergency Food Security Project (EFSP) – WBK/AF-2 | J4: Northeast / Kunduz | K4: Badakhshan | L4: Wardoj | M4: Saplings: 8184; Seeds kg: 495 | N4: World Bank (WBK/AF-2) | O4: Not awarded | P4: 7. Agroforestry Saplings-seeds | T4: IF(AQ4="","",AQ4) | U4: 46142 | V4: 12 | W4: 46478 | X4: IF(W4<>"",W4,IF(OR(T4="",V4=""),"",EDATE(T4,V4))) | AA4: Under Awarding | AB4: The saplings PO has already been issued and PO for seeds is expected to be issued in November 2026 | AC4: IF(F4="","",IF(COUNT(AI4:AV4)=0,IF(AA4="","Not started",AA4),SUBSTITUTE(LOOKUP(2,1/(AI4:AV4<>""),$AI$3:$AV$3),"Date: ",""))) | AD4: IF(OR(F4="",COUNT(AI4:AV4)=0),"",TODAY()-LOOKUP(2,1/(AI4:AV4<>""),AI4:AV4)) | AE4: IF(OR(F4="",COUNT(AI4:AV4)<2),"",LOOKUP(2,1/(AI4:AV4<>""),AI4:AV4)-MIN(AI4:AV4)) | AF4: IF(OR(AD4="",AC4="Not started",AC4=""),"",IFERROR(AD4-IF(VLOOKUP(AC4,'06_Status_Pipeline'!$B$3:$E$20,4,FALSE)="",0,VLOOKUP(AC4,'06_Status_Pipeline'!$B$3:$E$20,4,FALSE)),"")) | AG4: IF(F4="","",IF(OR(AA4="Cancelled",AC4="Cancelled"),"Cancelled",IF(OR(AC4="Completed / Handover",Y4<>"",Z4>=100),"Completed — on track",IF(O4="Not awarded",IF(U4="",IF(X4="","No planned date",IF(TODAY()>X4,"Behind — past planned date",IF(X4-TODAY()<=30,"At risk — close to off track","On track"))),IF(TODAY()>U4,"Behind — award date passed",IF(U4-TODAY()<=30,"At risk — close to off track","On track"))),IF(X4="","No planned date",IF(AND(TODAY()>X4,OR(Z4="",Z4<100)),"Behind — past end date",IF(AND(T4<>"",X4<>"",Z4<>"",(Z4<100),((TODAY()-T4)/MAX(X4-T4,1)*100)-Z4>15),"Behind — progress lag",IF(AND(X4-TODAY()<=30,X4-TODAY()>=0,OR(Z4="",Z4<90)),"At risk — close to off track","On track")))))))) | AH4: IF(OR(F4="",AC4="Completed / Handover",AC4="Cancelled"),"",IF(O4="Not awarded",IF(U4<>"",U4-TODAY(),IF(X4="","",X4-TODAY())),IF(X4="","",X4-TODAY()))) | AW4: IF(OR(F4="",AJ4=""),"",IF(COUNT(AI4:AI4)=0,"",AJ4-LOOKUP(2,1/(AI4:AI4<>""),AI4:AI4))) | AX4: IF(OR(F4="",AK4=""),"",IF(COUNT(AI4:AJ4)=0,"",AK4-LOOKUP(2,1/(AI4:AJ4<>""),AI4:AJ4))) | AY4: IF(OR(F4="",AL4=""),"",IF(COUNT(AI4:AK4)=0,"",AL4-LOOKUP(2,1/(AI4:AK4<>""),AI4:AK4))) | AZ4: IF(OR(F4="",AM4=""),"",IF(COUNT(AI4:AL4)=0,"",AM4-LOOKUP(2,1/(AI4:AL4<>""),AI4:AL4))) | BA4: IF(OR(F4="",AN4=""),"",IF(COUNT(AI4:AM4)=0,"",AN4-LOOKUP(2,1/(AI4:AM4<>""),AI4:AM4))) | BB4: IF(OR(F4="",AO4=""),"",IF(COUNT(AI4:AN4)=0,"",AO4-LOOKUP(2,1/(AI4:AN4<>""),AI4:AN4))) | BC4: IF(OR(F4="",AP4=""),"",IF(COUNT(AI4:AO4)=0,"",AP4-LOOKUP(2,1/(AI4:AO4<>""),AI4:AO4))) | BD4: IF(OR(F4="",AQ4=""),"",IF(COUNT(AI4:AP4)=0,"",AQ4-LOOKUP(2,1/(AI4:AP4<>""),AI4:AP4))) | BE4: IF(OR(F4="",AR4=""),"",IF(COUNT(AI4:AQ4)=0,"",AR4-LOOKUP(2,1/(AI4:AQ4<>""),AI4:AQ4))) | BF4: IF(OR(F4="",AS4=""),"",IF(COUNT(AI4:AR4)=0,"",AS4-LOOKUP(2,1/(AI4:AR4<>""),AI4:AR4))) | BG4: IF(OR(F4="",AT4=""),"",IF(COUNT(AI4:AS4)=0,"",AT4-LOOKUP(2,1/(AI4:AS4<>""),AI4:AS4))) | BH4: IF(OR(F4="",AU4=""),"",IF(COUNT(AI4:AT4)=0,"",AU4-LOOKUP(2,1/(AI4:AT4<>""),AI4:AT4))) | BI4: IF(OR(F4="",AV4=""),"",IF(COUNT(AI4:AU4)=0,"",AV4-LOOKUP(2,1/(AI4:AU4<>""),AI4:AU4))) | BJ4: IF(J4="","All_Provinces",IFERROR(VLOOKUP(J4,'09_Lookups'!$A$4:$B$20,2,FALSE),"All_Provinces")) | BK4: IF(K4="","All_Districts",IFERROR(VLOOKUP(K4,'09_Lookups'!$E$4:$F$42,2,FALSE),"All_Districts"))
A5: IF(F5="","",ROW()-3) | B5: AF2-AGF-ALL | C5: Agroforestry saplings and seeds 2026/27 | D5: 2 of 39 | E5: AF2-AGF-N-002 | F5: Agroforestry — Badghis / Sang Atish | G5: Agroforestry saplings / seeds | H5: Saplings and seeds | I5: Emergency Food Security Project (EFSP) – WBK/AF-2 | J5: West / Herat | K5: Badghis | L5: Sang Atish | M5: Saplings: 0; Seeds kg: 20 | N5: World Bank (WBK/AF-2) | O5: Not awarded | P5: 7. Agroforestry Saplings-seeds | T5: IF(AQ5="","",AQ5) | U5: 46142 | V5: 12 | W5: 46478 | X5: IF(W5<>"",W5,IF(OR(T5="",V5=""),"",EDATE(T5,V5))) | AA5: Under Awarding | AB5: The saplings PO has already been issued and PO for seeds is expected to be issued in November 2026 | AC5: IF(F5="","",IF(COUNT(AI5:AV5)=0,IF(AA5="","Not started",AA5),SUBSTITUTE(LOOKUP(2,1/(AI5:AV5<>""),$AI$3:$AV$3),"Date: ",""))) | AD5: IF(OR(F5="",COUNT(AI5:AV5)=0),"",TODAY()-LOOKUP(2,1/(AI5:AV5<>""),AI5:AV5)) | AE5: IF(OR(F5="",COUNT(AI5:AV5)<2),"",LOOKUP(2,1/(AI5:AV5<>""),AI5:AV5)-MIN(AI5:AV5)) | AF5: IF(OR(AD5="",AC5="Not started",AC5=""),"",IFERROR(AD5-IF(VLOOKUP(AC5,'06_Status_Pipeline'!$B$3:$E$20,4,FALSE)="",0,VLOOKUP(AC5,'06_Status_Pipeline'!$B$3:$E$20,4,FALSE)),"")) | AG5: IF(F5="","",IF(OR(AA5="Cancelled",AC5="Cancelled"),"Cancelled",IF(OR(AC5="Completed / Handover",Y5<>"",Z5>=100),"Completed — on track",IF(O5="Not awarded",IF(U5="",IF(X5="","No planned date",IF(TODAY()>X5,"Behind — past planned date",IF(X5-TODAY()<=30,"At risk — close to off track","On track"))),IF(TODAY()>U5,"Behind — award date passed",IF(U5-TODAY()<=30,"At risk — close to off track","On track"))),IF(X5="","No planned date",IF(AND(TODAY()>X5,OR(Z5="",Z5<100)),"Behind — past end date",IF(AND(T5<>"",X5<>"",Z5<>"",(Z5<100),((TODAY()-T5)/MAX(X5-T5,1)*100)-Z5>15),"Behind — progress lag",IF(AND(X5-TODAY()<=30,X5-TODAY()>=0,OR(Z5="",Z5<90)),"At risk — close to off track","On track")))))))) | AH5: IF(OR(F5="",AC5="Completed / Handover",AC5="Cancelled"),"",IF(O5="Not awarded",IF(U5<>"",U5-TODAY(),IF(X5="","",X5-TODAY())),IF(X5="","",X5-TODAY()))) | AW5: IF(OR(F5="",AJ5=""),"",IF(COUNT(AI5:AI5)=0,"",AJ5-LOOKUP(2,1/(AI5:AI5<>""),AI5:AI5))) | AX5: IF(OR(F5="",AK5=""),"",IF(COUNT(AI5:AJ5)=0,"",AK5-LOOKUP(2,1/(AI5:AJ5<>""),AI5:AJ5))) | AY5: IF(OR(F5="",AL5=""),"",IF(COUNT(AI5:AK5)=0,"",AL5-LOOKUP(2,1/(AI5:AK5<>""),AI5:AK5))) | AZ5: IF(OR(F5="",AM5=""),"",IF(COUNT(AI5:AL5)=0,"",AM5-LOOKUP(2,1/(AI5:AL5<>""),AI5:AL5))) | BA5: IF(OR(F5="",AN5=""),"",IF(COUNT(AI5:AM5)=0,"",AN5-LOOKUP(2,1/(AI5:AM5<>""),AI5:AM5))) | BB5: IF(OR(F5="",AO5=""),"",IF(COUNT(AI5:AN5)=0,"",AO5-LOOKUP(2,1/(AI5:AN5<>""),AI5:AN5))) | BC5: IF(OR(F5="",AP5=""),"",IF(COUNT(AI5:AO5)=0,"",AP5-LOOKUP(2,1/(AI5:AO5<>""),AI5:AO5))) | BD5: IF(OR(F5="",AQ5=""),"",IF(COUNT(AI5:AP5)=0,"",AQ5-LOOKUP(2,1/(AI5:AP5<>""),AI5:AP5))) | BE5: IF(OR(F5="",AR5=""),"",IF(COUNT(AI5:AQ5)=0,"",AR5-LOOKUP(2,1/(AI5:AQ5<>""),AI5:AQ5))) | BF5: IF(OR(F5="",AS5=""),"",IF(COUNT(AI5:AR5)=0,"",AS5-LOOKUP(2,1/(AI5:AR5<>""),AI5:AR5))) | BG5: IF(OR(F5="",AT5=""),"",IF(COUNT(AI5:AS5)=0,"",AT5-LOOKUP(2,1/(AI5:AS5<>""),AI5:AS5))) | BH5: IF(OR(F5="",AU5=""),"",IF(COUNT(AI5:AT5)=0,"",AU5-LOOKUP(2,1/(AI5:AT5<>""),AI5:AT5))) | BI5: IF(OR(F5="",AV5=""),"",IF(COUNT(AI5:AU5)=0,"",AV5-LOOKUP(2,1/(AI5:AU5<>""),AI5:AU5))) | BJ5: IF(J5="","All_Provinces",IFERROR(VLOOKUP(J5,'09_Lookups'!$A$4:$B$20,2,FALSE),"All_Provinces")) | BK5: IF(K5="","All_Districts",IFERROR(VLOOKUP(K5,'09_Lookups'!$E$4:$F$42,2,FALSE),"All_Districts"))
A6: IF(F6="","",ROW()-3) | B6: AF2-AGF-ALL | C6: Agroforestry saplings and seeds 2026/27 | D6: 3 of 39 | E6: AF2-AGF-N-003 | F6: Agroforestry — Baghlan / Banu | G6: Agroforestry saplings / seeds | H6: Saplings and seeds | I6: Emergency Food Security Project (EFSP) – WBK/AF-2 | J6: Northeast / Kunduz | K6: Baghlan | L6: Banu | M6: Saplings: 8316; Seeds kg: 121 | N6: World Bank (WBK/AF-2) | O6: Not awarded | P6: 7. Agroforestry Saplings-seeds | T6: IF(AQ6="","",AQ6) | U6: 46142 | V6: 12 | W6: 46478 | X6: IF(W6<>"",W6,IF(OR(T6="",V6=""),"",EDATE(T6,V6))) | AA6: Under Awarding | AB6: The saplings PO has already been issued and PO for seeds is expected to be issued in November 2026 | AC6: IF(F6="","",IF(COUNT(AI6:AV6)=0,IF(AA6="","Not started",AA6),SUBSTITUTE(LOOKUP(2,1/(AI6:AV6<>""),$AI$3:$AV$3),"Date: ",""))) | AD6: IF(OR(F6="",COUNT(AI6:AV6)=0),"",TODAY()-LOOKUP(2,1/(AI6:AV6<>""),AI6:AV6)) | AE6: IF(OR(F6="",COUNT(AI6:AV6)<2),"",LOOKUP(2,1/(AI6:AV6<>""),AI6:AV6)-MIN(AI6:AV6)) | AF6: IF(OR(AD6="",AC6="Not started",AC6=""),"",IFERROR(AD6-IF(VLOOKUP(AC6,'06_Status_Pipeline'!$B$3:$E$20,4,FALSE)="",0,VLOOKUP(AC6,'06_Status_Pipeline'!$B$3:$E$20,4,FALSE)),"")) | AG6: IF(F6="","",IF(OR(AA6="Cancelled",AC6="Cancelled"),"Cancelled",IF(OR(AC6="Completed / Handover",Y6<>"",Z6>=100),"Completed — on track",IF(O6="Not awarded",IF(U6="",IF(X6="","No planned date",IF(TODAY()>X6,"Behind — past planned date",IF(X6-TODAY()<=30,"At risk — close to off track","On track"))),IF(TODAY()>U6,"Behind — award date passed",IF(U6-TODAY()<=30,"At risk — close to off track","On track"))),IF(X6="","No planned date",IF(AND(TODAY()>X6,OR(Z6="",Z6<100)),"Behind — past end date",IF(AND(T6<>"",X6<>"",Z6<>"",(Z6<100),((TODAY()-T6)/MAX(X6-T6,1)*100)-Z6>15),"Behind — progress lag",IF(AND(X6-TODAY()<=30,X6-TODAY()>=0,OR(Z6="",Z6<90)),"At risk — close to off track","On track")))))))) | AH6: IF(OR(F6="",AC6="Completed / Handover",AC6="Cancelled"),"",IF(O6="Not awarded",IF(U6<>"",U6-TODAY(),IF(X6="","",X6-TODAY())),IF(X6="","",X6-TODAY()))) | AW6: IF(OR(F6="",AJ6=""),"",IF(COUNT(AI6:AI6)=0,"",AJ6-LOOKUP(2,1/(AI6:AI6<>""),AI6:AI6))) | AX6: IF(OR(F6="",AK6=""),"",IF(COUNT(AI6:AJ6)=0,"",AK6-LOOKUP(2,1/(AI6:AJ6<>""),AI6:AJ6))) | AY6: IF(OR(F6="",AL6=""),"",IF(COUNT(AI6:AK6)=0,"",AL6-LOOKUP(2,1/(AI6:AK6<>""),AI6:AK6))) | AZ6: IF(OR(F6="",AM6=""),"",IF(COUNT(AI6:AL6)=0,"",AM6-LOOKUP(2,1/(AI6:AL6<>""),AI6:AL6))) | BA6: IF(OR(F6="",AN6=""),"",IF(COUNT(AI6:AM6)=0,"",AN6-LOOKUP(2,1/(AI6:AM6<>""),AI6:AM6))) | BB6: IF(OR(F6="",AO6=""),"",IF(COUNT(AI6:AN6)=0,"",AO6-LOOKUP(2,1/(AI6:AN6<>""),AI6:AN6))) | BC6: IF(OR(F6="",AP6=""),"",IF(COUNT(AI6:AO6)=0,"",AP6-LOOKUP(2,1/(AI6:AO6<>""),AI6:AO6))) | BD6: IF(OR(F6="",AQ6=""),"",IF(COUNT(AI6:AP6)=0,"",AQ6-LOOKUP(2,1/(AI6:AP6<>""),AI6:AP6))) | BE6: IF(OR(F6="",AR6=""),"",IF(COUNT(AI6:AQ6)=0,"",AR6-LOOKUP(2,1/(AI6:AQ6<>""),AI6:AQ6))) | BF6: IF(OR(F6="",AS6=""),"",IF(COUNT(AI6:AR6)=0,"",AS6-LOOKUP(2,1/(AI6:AR6<>""),AI6:AR6))) | BG6: IF(OR(F6="",AT6=""),"",IF(COUNT(AI6:AS6)=0,"",AT6-LOOKUP(2,1/(AI6:AS6<>""),AI6:AS6))) | BH6: IF(OR(F6="",AU6=""),"",IF(COUNT(AI6:AT6)=0,"",AU6-LOOKUP(2,1/(AI6:AT6<>""),AI6:AT6))) | BI6: IF(OR(F6="",AV6=""),"",IF(COUNT(AI6:AU6)=0,"",AV6-LOOKUP(2,1/(AI6:AU6<>""),AI6:AU6))) | BJ6: IF(J6="","All_Provinces",IFERROR(VLOOKUP(J6,'09_Lookups'!$A$4:$B$20,2,FALSE),"All_Provinces")) | BK6: IF(K6="","All_Districts",IFERROR(VLOOKUP(K6,'09_Lookups'!$E$4:$F$42,2,FALSE),"All_Districts"))
A7: IF(F7="","",ROW()-3) | B7: AF2-AGF-ALL | C7: Agroforestry saplings and seeds 2026/27 | D7: 4 of 39 | E7: AF2-AGF-N-004 | F7: Agroforestry — Balkh / Charkent | G7: Agroforestry saplings / seeds | H7: Saplings and seeds | I7: Emergency Food Security Project (EFSP) – WBK/AF-2 | J7: North / Mazar | K7: Balkh | L7: Charkent | M7: Saplings: 0; Seeds kg: 31 | N7: World Bank (WBK/AF-2) | O7: Not awarded | P7: 7. Agroforestry Saplings-seeds | T7: IF(AQ7="","",AQ7) | U7: 46142 | V7: 12 | W7: 46478 | X7: IF(W7<>"",W7,IF(OR(T7="",V7=""),"",EDATE(T7,V7))) | AA7: Under Awarding | AB7: The saplings PO has already been issued and PO for seeds is expected to be issued in November 2026 | AC7: IF(F7="","",IF(COUNT(AI7:AV7)=0,IF(AA7="","Not started",AA7),SUBSTITUTE(LOOKUP(2,1/(AI7:AV7<>""),$AI$3:$AV$3),"Date: ",""))) | AD7: IF(OR(F7="",COUNT(AI7:AV7)=0),"",TODAY()-LOOKUP(2,1/(AI7:AV7<>""),AI7:AV7)) | AE7: IF(OR(F7="",COUNT(AI7:AV7)<2),"",LOOKUP(2,1/(AI7:AV7<>""),AI7:AV7)-MIN(AI7:AV7)) | AF7: IF(OR(AD7="",AC7="Not started",AC7=""),"",IFERROR(AD7-IF(VLOOKUP(AC7,'06_Status_Pipeline'!$B$3:$E$20,4,FALSE)="",0,VLOOKUP(AC7,'06_Status_Pipeline'!$B$3:$E$20,4,FALSE)),"")) | AG7: IF(F7="","",IF(OR(AA7="Cancelled",AC7="Cancelled"),"Cancelled",IF(OR(AC7="Completed / Handover",Y7<>"",Z7>=100),"Completed — on track",IF(O7="Not awarded",IF(U7="",IF(X7="","No planned date",IF(TODAY()>X7,"Behind — past planned date",IF(X7-TODAY()<=30,"At risk — close to off track","On track"))),IF(TODAY()>U7,"Behind — award date passed",IF(U7-TODAY()<=30,"At risk — close to off track","On track"))),IF(X7="","No planned date",IF(AND(TODAY()>X7,OR(Z7="",Z7<100)),"Behind — past end date",IF(AND(T7<>"",X7<>"",Z7<>"",(Z7<100),((TODAY()-T7)/MAX(X7-T7,1)*100)-Z7>15),"Behind — progress lag",IF(AND(X7-TODAY()<=30,X7-TODAY()>=0,OR(Z7="",Z7<90)),"At risk — close to off track","On track")))))))) | AH7: IF(OR(F7="",AC7="Completed / Handover",AC7="Cancelled"),"",IF(O7="Not awarded",IF(U7<>"",U7-TODAY(),IF(X7="","",X7-TODAY())),IF(X7="","",X7-TODAY()))) | AW7: IF(OR(F7="",AJ7=""),"",IF(COUNT(AI7:AI7)=0,"",AJ7-LOOKUP(2,1/(AI7:AI7<>""),AI7:AI7))) | AX7: IF(OR(F7="",AK7=""),"",IF(COUNT(AI7:AJ7)=0,"",AK7-LOOKUP(2,1/(AI7:AJ7<>""),AI7:AJ7))) | AY7: IF(OR(F7="",AL7=""),"",IF(COUNT(AI7:AK7)=0,"",AL7-LOOKUP(2,1/(AI7:AK7<>""),AI7:AK7))) | AZ7: IF(OR(F7="",AM7=""),"",IF(COUNT(AI7:AL7)=0,"",AM7-LOOKUP(2,1/(AI7:AL7<>""),AI7:AL7))) | BA7: IF(OR(F7="",AN7=""),"",IF(COUNT(AI7:AM7)=0,"",AN7-LOOKUP(2,1/(AI7:AM7<>""),AI7:AM7))) | BB7: IF(OR(F7="",AO7=""),"",IF(COUNT(AI7:AN7)=0,"",AO7-LOOKUP(2,1/(AI7:AN7<>""),AI7:AN7))) | BC7: IF(OR(F7="",AP7=""),"",IF(COUNT(AI7:AO7)=0,"",AP7-LOOKUP(2,1/(AI7:AO7<>""),AI7:AO7))) | BD7: IF(OR(F7="",AQ7=""),"",IF(COUNT(AI7:AP7)=0,"",AQ7-LOOKUP(2,1/(AI7:AP7<>""),AI7:AP7))) | BE7: IF(OR(F7="",AR7=""),"",IF(COUNT(AI7:AQ7)=0,"",AR7-LOOKUP(2,1/(AI7:AQ7<>""),AI7:AQ7))) | BF7: IF(OR(F7="",AS7=""),"",IF(COUNT(AI7:AR7)=0,"",AS7-LOOKUP(2,1/(AI7:AR7<>""),AI7:AR7))) | BG7: IF(OR(F7="",AT7=""),"",IF(COUNT(AI7:AS7)=0,"",AT7-LOOKUP(2,1/(AI7:AS7<>""),AI7:AS7))) | BH7: IF(OR(F7="",AU7=""),"",IF(COUNT(AI7:AT7)=0,"",AU7-LOOKUP(2,1/(AI7:AT7<>""),AI7:AT7))) | BI7: IF(OR(F7="",AV7=""),"",IF(COUNT(AI7:AU7)=0,"",AV7-LOOKUP(2,1/(AI7:AU7<>""),AI7:AU7))) | BJ7: IF(J7="","All_Provinces",IFERROR(VLOOKUP(J7,'09_Lookups'!$A$4:$B$20,2,FALSE),"All_Provinces")) | BK7: IF(K7="","All_Districts",IFERROR(VLOOKUP(K7,'09_Lookups'!$E$4:$F$42,2,FALSE),"All_Districts"))
A8: IF(F8="","",ROW()-3) | B8: AF2-AGF-ALL | C8: Agroforestry saplings and seeds 2026/27 | D8: 5 of 39 | E8: AF2-AGF-N-005 | F8: Agroforestry — Balkh / Dehdadi | G8: Agroforestry saplings / seeds | H8: Saplings and seeds | I8: Emergency Food Security Project (EFSP) – WBK/AF-2 | J8: North / Mazar | K8: Balkh | L8: Dehdadi | M8: Saplings: 2400; Seeds kg: 21 | N8: World Bank (WBK/AF-2) | O8: Not awarded | P8: 7. Agroforestry Saplings-seeds | T8: IF(AQ8="","",AQ8) | U8: 46142 | V8: 12 | W8: 46478 | X8: IF(W8<>"",W8,IF(OR(T8="",V8=""),"",EDATE(T8,V8))) | AA8: Under Awarding | AB8: The saplings PO has already been issued and PO for seeds is expected to be issued in November 2026 | AC8: IF(F8="","",IF(COUNT(AI8:AV8)=0,IF(AA8="","Not started",AA8),SUBSTITUTE(LOOKUP(2,1/(AI8:AV8<>""),$AI$3:$AV$3),"Date: ",""))) | AD8: IF(OR(F8="",COUNT(AI8:AV8)=0),"",TODAY()-LOOKUP(2,1/(AI8:AV8<>""),AI8:AV8)) | AE8: IF(OR(F8="",COUNT(AI8:AV8)<2),"",LOOKUP(2,1/(AI8:AV8<>""),AI8:AV8)-MIN(AI8:AV8)) | AF8: IF(OR(AD8="",AC8="Not started",AC8=""),"",IFERROR(AD8-IF(VLOOKUP(AC8,'06_Status_Pipeline'!$B$3:$E$20,4,FALSE)="",0,VLOOKUP(AC8,'06_Status_Pipeline'!$B$3:$E$20,4,FALSE)),"")) | AG8: IF(F8="","",IF(OR(AA8="Cancelled",AC8="Cancelled"),"Cancelled",IF(OR(AC8="Completed / Handover",Y8<>"",Z8>=100),"Completed — on track",IF(O8="Not awarded",IF(U8="",IF(X8="","No planned date",IF(TODAY()>X8,"Behind — past planned date",IF(X8-TODAY()<=30,"At risk — close to off track","On track"))),IF(TODAY()>U8,"Behind — award date passed",IF(U8-TODAY()<=30,"At risk — close to off track","On track"))),IF(X8="","No planned date",IF(AND(TODAY()>X8,OR(Z8="",Z8<100)),"Behind — past end date",IF(AND(T8<>"",X8<>"",Z8<>"",(Z8<100),((TODAY()-T8)/MAX(X8-T8,1)*100)-Z8>15),"Behind — progress lag",IF(AND(X8-TODAY()<=30,X8-TODAY()>=0,OR(Z8="",Z8<90)),"At risk — close to off track","On track")))))))) | AH8: IF(OR(F8="",AC8="Completed / Handover",AC8="Cancelled"),"",IF(O8="Not awarded",IF(U8<>"",U8-TODAY(),IF(X8="","",X8-TODAY())),IF(X8="","",X8-TODAY()))) | AW8: IF(OR(F8="",AJ8=""),"",IF(COUNT(AI8:AI8)=0,"",AJ8-LOOKUP(2,1/(AI8:AI8<>""),AI8:AI8))) | AX8: IF(OR(F8="",AK8=""),"",IF(COUNT(AI8:AJ8)=0,"",AK8-LOOKUP(2,1/(AI8:AJ8<>""),AI8:AJ8))) | AY8: IF(OR(F8="",AL8=""),"",IF(COUNT(AI8:AK8)=0,"",AL8-LOOKUP(2,1/(AI8:AK8<>""),AI8:AK8))) | AZ8: IF(OR(F8="",AM8=""),"",IF(COUNT(AI8:AL8)=0,"",AM8-LOOKUP(2,1/(AI8:AL8<>""),AI8:AL8))) | BA8: IF(OR(F8="",AN8=""),"",IF(COUNT(AI8:AM8)=0,"",AN8-LOOKUP(2,1/(AI8:AM8<>""),AI8:AM8))) | BB8: IF(OR(F8="",AO8=""),"",IF(COUNT(AI8:AN8)=0,"",AO8-LOOKUP(2,1/(AI8:AN8<>""),AI8:AN8))) | BC8: IF(OR(F8="",AP8=""),"",IF(COUNT(AI8:AO8)=0,"",AP8-LOOKUP(2,1/(AI8:AO8<>""),AI8:AO8))) | BD8: IF(OR(F8="",AQ8=""),"",IF(COUNT(AI8:AP8)=0,"",AQ8-LOOKUP(2,1/(AI8:AP8<>""),AI8:AP8))) | BE8: IF(OR(F8="",AR8=""),"",IF(COUNT(AI8:AQ8)=0,"",AR8-LOOKUP(2,1/(AI8:AQ8<>""),AI8:AQ8))) | BF8: IF(OR(F8="",AS8=""),"",IF(COUNT(AI8:AR8)=0,"",AS8-LOOKUP(2,1/(AI8:AR8<>""),AI8:AR8))) | BG8: IF(OR(F8="",AT8=""),"",IF(COUNT(AI8:AS8)=0,"",AT8-LOOKUP(2,1/(AI8:AS8<>""),AI8:AS8))) | BH8: IF(OR(F8="",AU8=""),"",IF(COUNT(AI8:AT8)=0,"",AU8-LOOKUP(2,1/(AI8:AT8<>""),AI8:AT8))) | BI8: IF(OR(F8="",AV8=""),"",IF(COUNT(AI8:AU8)=0,"",AV8-LOOKUP(2,1/(AI8:AU8<>""),AI8:AU8))) | BJ8: IF(J8="","All_Provinces",IFERROR(VLOOKUP(J8,'09_Lookups'!$A$4:$B$20,2,FALSE),"All_Provinces")) | BK8: IF(K8="","All_Districts",IFERROR(VLOOKUP(K8,'09_Lookups'!$E$4:$F$42,2,FALSE),"All_Districts"))
A9: IF(F9="","",ROW()-3) | B9: AF2-AGF-ALL | C9: Agroforestry saplings and seeds 2026/27 | D9: 6 of 39 | E9: AF2-AGF-N-006 | F9: Agroforestry — Balkh / Kishendeh | G9: Agroforestry saplings / seeds | H9: Saplings and seeds | I9: Emergency Food Security Project (EFSP) – WBK/AF-2 | J9: North / Mazar | K9: Balkh | L9: Kishendeh | M9: Saplings: 0; Seeds kg: 46 | N9: World Bank (WBK/AF-2) | O9: Not awarded | P9: 7. Agroforestry Saplings-seeds | T9: IF(AQ9="","",AQ9) | U9: 46142 | V9: 12 | W9: 46478 | X9: IF(W9<>"",W9,IF(OR(T9="",V9=""),"",EDATE(T9,V9))) | AA9: Under Awarding | AB9: The saplings PO has already been issued and PO for seeds is expected to be issued in November 2026 | AC9: IF(F9="","",IF(COUNT(AI9:AV9)=0,IF(AA9="","Not started",AA9),SUBSTITUTE(LOOKUP(2,1/(AI9:AV9<>""),$AI$3:$AV$3),"Date: ",""))) | AD9: IF(OR(F9="",COUNT(AI9:AV9)=0),"",TODAY()-LOOKUP(2,1/(AI9:AV9<>""),AI9:AV9)) | AE9: IF(OR(F9="",COUNT(AI9:AV9)<2),"",LOOKUP(2,1/(AI9:AV9<>""),AI9:AV9)-MIN(AI9:AV9)) | AF9: IF(OR(AD9="",AC9="Not started",AC9=""),"",IFERROR(AD9-IF(VLOOKUP(AC9,'06_Status_Pipeline'!$B$3:$E$20,4,FALSE)="",0,VLOOKUP(AC9,'06_Status_Pipeline'!$B$3:$E$20,4,FALSE)),"")) | AG9: IF(F9="","",IF(OR(AA9="Cancelled",AC9="Cancelled"),"Cancelled",IF(OR(AC9="Completed / Handover",Y9<>"",Z9>=100),"Completed — on track",IF(O9="Not awarded",IF(U9="",IF(X9="","No planned date",IF(TODAY()>X9,"Behind — past planned date",IF(X9-TODAY()<=30,"At risk — close to off track","On track"))),IF(TODAY()>U9,"Behind — award date passed",IF(U9-TODAY()<=30,"At risk — close to off track","On track"))),IF(X9="","No planned date",IF(AND(TODAY()>X9,OR(Z9="",Z9<100)),"Behind — past end date",IF(AND(T9<>"",X9<>"",Z9<>"",(Z9<100),((TODAY()-T9)/MAX(X9-T9,1)*100)-Z9>15),"Behind — progress lag",IF(AND(X9-TODAY()<=30,X9-TODAY()>=0,OR(Z9="",Z9<90)),"At risk — close to off track","On track")))))))) | AH9: IF(OR(F9="",AC9="Completed / Handover",AC9="Cancelled"),"",IF(O9="Not awarded",IF(U9<>"",U9-TODAY(),IF(X9="","",X9-TODAY())),IF(X9="","",X9-TODAY()))) | AW9: IF(OR(F9="",AJ9=""),"",IF(COUNT(AI9:AI9)=0,"",AJ9-LOOKUP(2,1/(AI9:AI9<>""),AI9:AI9))) | AX9: IF(OR(F9="",AK9=""),"",IF(COUNT(AI9:AJ9)=0,"",AK9-LOOKUP(2,1/(AI9:AJ9<>""),AI9:AJ9))) | AY9: IF(OR(F9="",AL9=""),"",IF(COUNT(AI9:AK9)=0,"",AL9-LOOKUP(2,1/(AI9:AK9<>""),AI9:AK9))) | AZ9: IF(OR(F9="",AM9=""),"",IF(COUNT(AI9:AL9)=0,"",AM9-LOOKUP(2,1/(AI9:AL9<>""),AI9:AL9))) | BA9: IF(OR(F9="",AN9=""),"",IF(COUNT(AI9:AM9)=0,"",AN9-LOOKUP(2,1/(AI9:AM9<>""),AI9:AM9))) | BB9: IF(OR(F9="",AO9=""),"",IF(COUNT(AI9:AN9)=0,"",AO9-LOOKUP(2,1/(AI9:AN9<>""),AI9:AN9))) | BC9: IF(OR(F9="",AP9=""),"",IF(COUNT(AI9:AO9)=0,"",AP9-LOOKUP(2,1/(AI9:AO9<>""),AI9:AO9))) | BD9: IF(OR(F9="",AQ9=""),"",IF(COUNT(AI9:AP9)=0,"",AQ9-LOOKUP(2,1/(AI9:AP9<>""),AI9:AP9))) | BE9: IF(OR(F9="",AR9=""),"",IF(COUNT(AI9:AQ9)=0,"",AR9-LOOKUP(2,1/(AI9:AQ9<>""),AI9:AQ9))) | BF9: IF(OR(F9="",AS9=""),"",IF(COUNT(AI9:AR9)=0,"",AS9-LOOKUP(2,1/(AI9:AR9<>""),AI9:AR9))) | BG9: IF(OR(F9="",AT9=""),"",IF(COUNT(AI9:AS9)=0,"",AT9-LOOKUP(2,1/(AI9:AS9<>""),AI9:AS9))) | BH9: IF(OR(F9="",AU9=""),"",IF(COUNT(AI9:AT9)=0,"",AU9-LOOKUP(2,1/(AI9:AT9<>""),AI9:AT9))) | BI9: IF(OR(F9="",AV9=""),"",IF(COUNT(AI9:AU9)=0,"",AV9-LOOKUP(2,1/(AI9:AU9<>""),AI9:AU9))) | BJ9: IF(J9="","All_Provinces",IFERROR(VLOOKUP(J9,'09_Lookups'!$A$4:$B$20,2,FALSE),"All_Provinces")) | BK9: IF(K9="","All_Districts",IFERROR(VLOOKUP(K9,'09_Lookups'!$E$4:$F$42,2,FALSE),"All_Districts"))
A10: IF(F10="","",ROW()-3) | B10: AF2-AGF-ALL | C10: Agroforestry saplings and seeds 2026/27 | D10: 7 of 39 | E10: AF2-AGF-N-007 | F10: Agroforestry — Balkh / Marmul | G10: Agroforestry saplings / seeds | H10: Saplings and seeds | I10: Emergency Food Security Project (EFSP) – WBK/AF-2 | J10: North / Mazar | K10: Balkh | L10: Marmul | M10: Saplings: 0; Seeds kg: 41 | N10: World Bank (WBK/AF-2) | O10: Not awarded | P10: 7. Agroforestry Saplings-seeds | T10: IF(AQ10="","",AQ10) | U10: 46142 | V10: 12 | W10: 46478 | X10: IF(W10<>"",W10,IF(OR(T10="",V10=""),"",EDATE(T10,V10))) | AA10: Under Awarding | AB10: The saplings PO has already been issued and PO for seeds is expected to be issued in November 2026 | AC10: IF(F10="","",IF(COUNT(AI10:AV10)=0,IF(AA10="","Not started",AA10),SUBSTITUTE(LOOKUP(2,1/(AI10:AV10<>""),$AI$3:$AV$3),"Date: ",""))) | AD10: IF(OR(F10="",COUNT(AI10:AV10)=0),"",TODAY()-LOOKUP(2,1/(AI10:AV10<>""),AI10:AV10)) | AE10: IF(OR(F10="",COUNT(AI10:AV10)<2),"",LOOKUP(2,1/(AI10:AV10<>""),AI10:AV10)-MIN(AI10:AV10)) | AF10: IF(OR(AD10="",AC10="Not started",AC10=""),"",IFERROR(AD10-IF(VLOOKUP(AC10,'06_Status_Pipeline'!$B$3:$E$20,4,FALSE)="",0,VLOOKUP(AC10,'06_Status_Pipeline'!$B$3:$E$20,4,FALSE)),"")) | AG10: IF(F10="","",IF(OR(AA10="Cancelled",AC10="Cancelled"),"Cancelled",IF(OR(AC10="Completed / Handover",Y10<>"",Z10>=100),"Completed — on track",IF(O10="Not awarded",IF(U10="",IF(X10="","No planned date",IF(TODAY()>X10,"Behind — past planned date",IF(X10-TODAY()<=30,"At risk — close to off track","On track"))),IF(TODAY()>U10,"Behind — award date passed",IF(U10-TODAY()<=30,"At risk — close to off track","On track"))),IF(X10="","No planned date",IF(AND(TODAY()>X10,OR(Z10="",Z10<100)),"Behind — past end date",IF(AND(T10<>"",X10<>"",Z10<>"",(Z10<100),((TODAY()-T10)/MAX(X10-T10,1)*100)-Z10>15),"Behind — progress lag",IF(AND(X10-TODAY()<=30,X10-TODAY()>=0,OR(Z10="",Z10<90)),"At risk — close to off track","On track")))))))) | AH10: IF(OR(F10="",AC10="Completed / Handover",AC10="Cancelled"),"",IF(O10="Not awarded",IF(U10<>"",U10-TODAY(),IF(X10="","",X10-TODAY())),IF(X10="","",X10-TODAY()))) | AW10: IF(OR(F10="",AJ10=""),"",IF(COUNT(AI10:AI10)=0,"",AJ10-LOOKUP(2,1/(AI10:AI10<>""),AI10:AI10))) | AX10: IF(OR(F10="",AK10=""),"",IF(COUNT(AI10:AJ10)=0,"",AK10-LOOKUP(2,1/(AI10:AJ10<>""),AI10:AJ10))) | AY10: IF(OR(F10="",AL10=""),"",IF(COUNT(AI10:AK10)=0,"",AL10-LOOKUP(2,1/(AI10:AK10<>""),AI10:AK10))) | AZ10: IF(OR(F10="",AM10=""),"",IF(COUNT(AI10:AL10)=0,"",AM10-LOOKUP(2,1/(AI10:AL10<>""),AI10:AL10))) | BA10: IF(OR(F10="",AN10=""),"",IF(COUNT(AI10:AM10)=0,"",AN10-LOOKUP(2,1/(AI10:AM10<>""),AI10:AM10))) | BB10: IF(OR(F10="",AO10=""),"",IF(COUNT(AI10:AN10)=0,"",AO10-LOOKUP(2,1/(AI10:AN10<>""),AI10:AN10))) | BC10: IF(OR(F10="",AP10=""),"",IF(COUNT(AI10:AO10)=0,"",AP10-LOOKUP(2,1/(AI10:AO10<>""),AI10:AO10))) | BD10: IF(OR(F10="",AQ10=""),"",IF(COUNT(AI10:AP10)=0,"",AQ10-LOOKUP(2,1/(AI10:AP10<>""),AI10:AP10))) | BE10: IF(OR(F10="",AR10=""),"",IF(COUNT(AI10:AQ10)=0,"",AR10-LOOKUP(2,1/(AI10:AQ10<>""),AI10:AQ10))) | BF10: IF(OR(F10="",AS10=""),"",IF(COUNT(AI10:AR10)=0,"",AS10-LOOKUP(2,1/(AI10:AR10<>""),AI10:AR10))) | BG10: IF(OR(F10="",AT10=""),"",IF(COUNT(AI10:AS10)=0,"",AT10-LOOKUP(2,1/(AI10:AS10<>""),AI10:AS10))) | BH10: IF(OR(F10="",AU10=""),"",IF(COUNT(AI10:AT10)=0,"",AU10-LOOKUP(2,1/(AI10:AT10<>""),AI10:AT10))) | BI10: IF(OR(F10="",AV10=""),"",IF(COUNT(AI10:AU10)=0,"",AV10-LOOKUP(2,1/(AI10:AU10<>""),AI10:AU10))) | BJ10: IF(J10="","All_Provinces",IFERROR(VLOOKUP(J10,'09_Lookups'!$A$4:$B$20,2,FALSE),"All_Provinces")) | BK10: IF(K10="","All_Districts",IFERROR(VLOOKUP(K10,'09_Lookups'!$E$4:$F$42,2,FALSE),"All_Districts"))
A11: IF(F11="","",ROW()-3) | B11: AF2-AGF-ALL | C11: Agroforestry saplings and seeds 2026/27 | D11: 8 of 39 | E11: AF2-AGF-N-008 | F11: Agroforestry — Balkh / Nahre Shahi | G11: Agroforestry saplings / seeds | H11: Saplings and seeds | I11: Emergency Food Security Project (EFSP) – WBK/AF-2 | J11: North / Mazar | K11: Balkh | L11: Nahre Shahi | M11: Saplings: 0; Seeds kg: 246 | N11: World Bank (WBK/AF-2) | O11: Not awarded | P11: 7. Agroforestry Saplings-seeds | T11: IF(AQ11="","",AQ11) | U11: 46142 | V11: 12 | W11: 46478 | X11: IF(W11<>"",W11,IF(OR(T11="",V11=""),"",EDATE(T11,V11))) | AA11: Under Awarding | AB11: The saplings PO has already been issued and PO for seeds is expected to be issued in November 2026 | AC11: IF(F11="","",IF(COUNT(AI11:AV11)=0,IF(AA11="","Not started",AA11),SUBSTITUTE(LOOKUP(2,1/(AI11:AV11<>""),$AI$3:$AV$3),"Date: ",""))) | AD11: IF(OR(F11="",COUNT(AI11:AV11)=0),"",TODAY()-LOOKUP(2,1/(AI11:AV11<>""),AI11:AV11)) | AE11: IF(OR(F11="",COUNT(AI11:AV11)<2),"",LOOKUP(2,1/(AI11:AV11<>""),AI11:AV11)-MIN(AI11:AV11)) | AF11: IF(OR(AD11="",AC11="Not started",AC11=""),"",IFERROR(AD11-IF(VLOOKUP(AC11,'06_Status_Pipeline'!$B$3:$E$20,4,FALSE)="",0,VLOOKUP(AC11,'06_Status_Pipeline'!$B$3:$E$20,4,FALSE)),"")) | AG11: IF(F11="","",IF(OR(AA11="Cancelled",AC11="Cancelled"),"Cancelled",IF(OR(AC11="Completed / Handover",Y11<>"",Z11>=100),"Completed — on track",IF(O11="Not awarded",IF(U11="",IF(X11="","No planned date",IF(TODAY()>X11,"Behind — past planned date",IF(X11-TODAY()<=30,"At risk — close to off track","On track"))),IF(TODAY()>U11,"Behind — award date passed",IF(U11-TODAY()<=30,"At risk — close to off track","On track"))),IF(X11="","No planned date",IF(AND(TODAY()>X11,OR(Z11="",Z11<100)),"Behind — past end date",IF(AND(T11<>"",X11<>"",Z11<>"",(Z11<100),((TODAY()-T11)/MAX(X11-T11,1)*100)-Z11>15),"Behind — progress lag",IF(AND(X11-TODAY()<=30,X11-TODAY()>=0,OR(Z11="",Z11<90)),"At risk — close to off track","On track")))))))) | AH11: IF(OR(F11="",AC11="Completed / Handover",AC11="Cancelled"),"",IF(O11="Not awarded",IF(U11<>"",U11-TODAY(),IF(X11="","",X11-TODAY())),IF(X11="","",X11-TODAY()))) | AW11: IF(OR(F11="",AJ11=""),"",IF(COUNT(AI11:AI11)=0,"",AJ11-LOOKUP(2,1/(AI11:AI11<>""),AI11:AI11))) | AX11: IF(OR(F11="",AK11=""),"",IF(COUNT(AI11:AJ11)=0,"",AK11-LOOKUP(2,1/(AI11:AJ11<>""),AI11:AJ11))) | AY11: IF(OR(F11="",AL11=""),"",IF(COUNT(AI11:AK11)=0,"",AL11-LOOKUP(2,1/(AI11:AK11<>""),AI11:AK11))) | AZ11: IF(OR(F11="",AM11=""),"",IF(COUNT(AI11:AL11)=0,"",AM11-LOOKUP(2,1/(AI11:AL11<>""),AI11:AL11))) | BA11: IF(OR(F11="",AN11=""),"",IF(COUNT(AI11:AM11)=0,"",AN11-LOOKUP(2,1/(AI11:AM11<>""),AI11:AM11))) | BB11: IF(OR(F11="",AO11=""),"",IF(COUNT(AI11:AN11)=0,"",AO11-LOOKUP(2,1/(AI11:AN11<>""),AI11:AN11))) | BC11: IF(OR(F11="",AP11=""),"",IF(COUNT(AI11:AO11)=0,"",AP11-LOOKUP(2,1/(AI11:AO11<>""),AI11:AO11))) | BD11: IF(OR(F11="",AQ11=""),"",IF(COUNT(AI11:AP11)=0,"",AQ11-LOOKUP(2,1/(AI11:AP11<>""),AI11:AP11))) | BE11: IF(OR(F11="",AR11=""),"",IF(COUNT(AI11:AQ11)=0,"",AR11-LOOKUP(2,1/(AI11:AQ11<>""),AI11:AQ11))) | BF11: IF(OR(F11="",AS11=""),"",IF(COUNT(AI11:AR11)=0,"",AS11-LOOKUP(2,1/(AI11:AR11<>""),AI11:AR11))) | BG11: IF(OR(F11="",AT11=""),"",IF(COUNT(AI11:AS11)=0,"",AT11-LOOKUP(2,1/(AI11:AS11<>""),AI11:AS11))) | BH11: IF(OR(F11="",AU11=""),"",IF(COUNT(AI11:AT11)=0,"",AU11-LOOKUP(2,1/(AI11:AT11<>""),AI11:AT11))) | BI11: IF(OR(F11="",AV11=""),"",IF(COUNT(AI11:AU11)=0,"",AV11-LOOKUP(2,1/(AI11:AU11<>""),AI11:AU11))) | BJ11: IF(J11="","All_Provinces",IFERROR(VLOOKUP(J11,'09_Lookups'!$A$4:$B$20,2,FALSE),"All_Provinces")) | BK11: IF(K11="","All_Districts",IFERROR(VLOOKUP(K11,'09_Lookups'!$E$4:$F$42,2,FALSE),"All_Districts"))
A12: IF(F12="","",ROW()-3) | B12: AF2-AGF-ALL | C12: Agroforestry saplings and seeds 2026/27 | D12: 9 of 39 | E12: AF2-AGF-N-009 | F12: Agroforestry — Daikundi / Khedir | G12: Agroforestry saplings / seeds | H12: Saplings and seeds | I12: Emergency Food Security Project (EFSP) – WBK/AF-2 | J12: Central Highland / Bamyan | K12: Daikundi | L12: Khedir | M12: Saplings: 6000; Seeds kg: 477 | N12: World Bank (WBK/AF-2) | O12: Not awarded | P12: 7. Agroforestry Saplings-seeds | T12: IF(AQ12="","",AQ12) | U12: 46142 | V12: 12 | W12: 46478 | X12: IF(W12<>"",W12,IF(OR(T12="",V12=""),"",EDATE(T12,V12))) | AA12: Under Awarding | AB12: The saplings PO has already been issued and PO for seeds is expected to be issued in November 2026 | AC12: IF(F12="","",IF(COUNT(AI12:AV12)=0,IF(AA12="","Not started",AA12),SUBSTITUTE(LOOKUP(2,1/(AI12:AV12<>""),$AI$3:$AV$3),"Date: ",""))) | AD12: IF(OR(F12="",COUNT(AI12:AV12)=0),"",TODAY()-LOOKUP(2,1/(AI12:AV12<>""),AI12:AV12)) | AE12: IF(OR(F12="",COUNT(AI12:AV12)<2),"",LOOKUP(2,1/(AI12:AV12<>""),AI12:AV12)-MIN(AI12:AV12)) | AF12: IF(OR(AD12="",AC12="Not started",AC12=""),"",IFERROR(AD12-IF(VLOOKUP(AC12,'06_Status_Pipeline'!$B$3:$E$20,4,FALSE)="",0,VLOOKUP(AC12,'06_Status_Pipeline'!$B$3:$E$20,4,FALSE)),"")) | AG12: IF(F12="","",IF(OR(AA12="Cancelled",AC12="Cancelled"),"Cancelled",IF(OR(AC12="Completed / Handover",Y12<>"",Z12>=100),"Completed — on track",IF(O12="Not awarded",IF(U12="",IF(X12="","No planned date",IF(TODAY()>X12,"Behind — past planned date",IF(X12-TODAY()<=30,"At risk — close to off track","On track"))),IF(TODAY()>U12,"Behind — award date passed",IF(U12-TODAY()<=30,"At risk — close to off track","On track"))),IF(X12="","No planned date",IF(AND(TODAY()>X12,OR(Z12="",Z12<100)),"Behind — past end date",IF(AND(T12<>"",X12<>"",Z12<>"",(Z12<100),((TODAY()-T12)/MAX(X12-T12,1)*100)-Z12>15),"Behind — progress lag",IF(AND(X12-TODAY()<=30,X12-TODAY()>=0,OR(Z12="",Z12<90)),"At risk — close to off track","On track")))))))) | AH12: IF(OR(F12="",AC12="Completed / Handover",AC12="Cancelled"),"",IF(O12="Not awarded",IF(U12<>"",U12-TODAY(),IF(X12="","",X12-TODAY())),IF(X12="","",X12-TODAY()))) | AW12: IF(OR(F12="",AJ12=""),"",IF(COUNT(AI12:AI12)=0,"",AJ12-LOOKUP(2,1/(AI12:AI12<>""),AI12:AI12))) | AX12: IF(OR(F12="",AK12=""),"",IF(COUNT(AI12:AJ12)=0,"",AK12-LOOKUP(2,1/(AI12:AJ12<>""),AI12:AJ12))) | AY12: IF(OR(F12="",AL12=""),"",IF(COUNT(AI12:AK12)=0,"",AL12-LOOKUP(2,1/(AI12:AK12<>""),AI12:AK12))) | AZ12: IF(OR(F12="",AM12=""),"",IF(COUNT(AI12:AL12)=0,"",AM12-LOOKUP(2,1/(AI12:AL12<>""),AI12:AL12))) | BA12: IF(OR(F12="",AN12=""),"",IF(COUNT(AI12:AM12)=0,"",AN12-LOOKUP(2,1/(AI12:AM12<>""),AI12:AM12))) | BB12: IF(OR(F12="",AO12=""),"",IF(COUNT(AI12:AN12)=0,"",AO12-LOOKUP(2,1/(AI12:AN12<>""),AI12:AN12))) | BC12: IF(OR(F12="",AP12=""),"",IF(COUNT(AI12:AO12)=0,"",AP12-LOOKUP(2,1/(AI12:AO12<>""),AI12:AO12))) | BD12: IF(OR(F12="",AQ12=""),"",IF(COUNT(AI12:AP12)=0,"",AQ12-LOOKUP(2,1/(AI12:AP12<>""),AI12:AP12))) | BE12: IF(OR(F12="",AR12=""),"",IF(COUNT(AI12:AQ12)=0,"",AR12-LOOKUP(2,1/(AI12:AQ12<>""),AI12:AQ12))) | BF12: IF(OR(F12="",AS12=""),"",IF(COUNT(AI12:AR12)=0,"",AS12-LOOKUP(2,1/(AI12:AR12<>""),AI12:AR12))) | BG12: IF(OR(F12="",AT12=""),"",IF(COUNT(AI12:AS12)=0,"",AT12-LOOKUP(2,1/(AI12:AS12<>""),AI12:AS12))) | BH12: IF(OR(F12="",AU12=""),"",IF(COUNT(AI12:AT12)=0,"",AU12-LOOKUP(2,1/(AI12:AT12<>""),AI12:AT12))) | BI12: IF(OR(F12="",AV12=""),"",IF(COUNT(AI12:AU12)=0,"",AV12-LOOKUP(2,1/(AI12:AU12<>""),AI12:AU12))) | BJ12: IF(J12="","All_Provinces",IFERROR(VLOOKUP(J12,'09_Lookups'!$A$4:$B$20,2,FALSE),"All_Provinces")) | BK12: IF(K12="","All_Districts",IFERROR(VLOOKUP(K12,'09_Lookups'!$E$4:$F$42,2,FALSE),"All_Districts"))
A13: IF(F13="","",ROW()-3) | B13: AF2-AGF-ALL | C13: Agroforestry saplings and seeds 2026/27 | D13: 10 of 39 | E13: AF2-AGF-N-010 | F13: Agroforestry — Daikundi / Meramour | G13: Agroforestry saplings / seeds | H13: Saplings and seeds | I13: Emergency Food Security Project (EFSP) – WBK/AF-2 | J13: Central Highland / Bamyan | K13: Daikundi | L13: Meramour | M13: Saplings: 7000; Seeds kg: 197.5 | N13: World Bank (WBK/AF-2) | O13: Not awarded | P13: 7. Agroforestry Saplings-seeds | T13: IF(AQ13="","",AQ13) | U13: 46142 | V13: 12 | W13: 46478 | X13: IF(W13<>"",W13,IF(OR(T13="",V13=""),"",EDATE(T13,V13))) | AA13: Under Awarding | AB13: The saplings PO has already been issued and PO for seeds is expected to be issued in November 2026 | AC13: IF(F13="","",IF(COUNT(AI13:AV13)=0,IF(AA13="","Not started",AA13),SUBSTITUTE(LOOKUP(2,1/(AI13:AV13<>""),$AI$3:$AV$3),"Date: ",""))) | AD13: IF(OR(F13="",COUNT(AI13:AV13)=0),"",TODAY()-LOOKUP(2,1/(AI13:AV13<>""),AI13:AV13)) | AE13: IF(OR(F13="",COUNT(AI13:AV13)<2),"",LOOKUP(2,1/(AI13:AV13<>""),AI13:AV13)-MIN(AI13:AV13)) | AF13: IF(OR(AD13="",AC13="Not started",AC13=""),"",IFERROR(AD13-IF(VLOOKUP(AC13,'06_Status_Pipeline'!$B$3:$E$20,4,FALSE)="",0,VLOOKUP(AC13,'06_Status_Pipeline'!$B$3:$E$20,4,FALSE)),"")) | AG13: IF(F13="","",IF(OR(AA13="Cancelled",AC13="Cancelled"),"Cancelled",IF(OR(AC13="Completed / Handover",Y13<>"",Z13>=100),"Completed — on track",IF(O13="Not awarded",IF(U13="",IF(X13="","No planned date",IF(TODAY()>X13,"Behind — past planned date",IF(X13-TODAY()<=30,"At risk — close to off track","On track"))),IF(TODAY()>U13,"Behind — award date passed",IF(U13-TODAY()<=30,"At risk — close to off track","On track"))),IF(X13="","No planned date",IF(AND(TODAY()>X13,OR(Z13="",Z13<100)),"Behind — past end date",IF(AND(T13<>"",X13<>"",Z13<>"",(Z13<100),((TODAY()-T13)/MAX(X13-T13,1)*100)-Z13>15),"Behind — progress lag",IF(AND(X13-TODAY()<=30,X13-TODAY()>=0,OR(Z13="",Z13<90)),"At risk — close to off track","On track")))))))) | AH13: IF(OR(F13="",AC13="Completed / Handover",AC13="Cancelled"),"",IF(O13="Not awarded",IF(U13<>"",U13-TODAY(),IF(X13="","",X13-TODAY())),IF(X13="","",X13-TODAY()))) | AW13: IF(OR(F13="",AJ13=""),"",IF(COUNT(AI13:AI13)=0,"",AJ13-LOOKUP(2,1/(AI13:AI13<>""),AI13:AI13))) | AX13: IF(OR(F13="",AK13=""),"",IF(COUNT(AI13:AJ13)=0,"",AK13-LOOKUP(2,1/(AI13:AJ13<>""),AI13:AJ13))) | AY13: IF(OR(F13="",AL13=""),"",IF(COUNT(AI13:AK13)=0,"",AL13-LOOKUP(2,1/(AI13:AK13<>""),AI13:AK13))) | AZ13: IF(OR(F13="",AM13=""),"",IF(COUNT(AI13:AL13)=0,"",AM13-LOOKUP(2,1/(AI13:AL13<>""),AI13:AL13))) | BA13: IF(OR(F13="",AN13=""),"",IF(COUNT(AI13:AM13)=0,"",AN13-LOOKUP(2,1/(AI13:AM13<>""),AI13:AM13))) | BB13: IF(OR(F13="",AO13=""),"",IF(COUNT(AI13:AN13)=0,"",AO13-LOOKUP(2,1/(AI13:AN13<>""),AI13:AN13))) | BC13: IF(OR(F13="",AP13=""),"",IF(COUNT(AI13:AO13)=0,"",AP13-LOOKUP(2,1/(AI13:AO13<>""),AI13:AO13))) | BD13: IF(OR(F13="",AQ13=""),"",IF(COUNT(AI13:AP13)=0,"",AQ13-LOOKUP(2,1/(AI13:AP13<>""),AI13:AP13))) | BE13: IF(OR(F13="",AR13=""),"",IF(COUNT(AI13:AQ13)=0,"",AR13-LOOKUP(2,1/(AI13:AQ13<>""),AI13:AQ13))) | BF13: IF(OR(F13="",AS13=""),"",IF(COUNT(AI13:AR13)=0,"",AS13-LOOKUP(2,1/(AI13:AR13<>""),AI13:AR13))) | BG13: IF(OR(F13="",AT13=""),"",IF(COUNT(AI13:AS13)=0,"",AT13-LOOKUP(2,1/(AI13:AS13<>""),AI13:AS13))) | BH13: IF(OR(F13="",AU13=""),"",IF(COUNT(AI13:AT13)=0,"",AU13-LOOKUP(2,1/(AI13:AT13<>""),AI13:AT13))) | BI13: IF(OR(F13="",AV13=""),"",IF(COUNT(AI13:AU13)=0,"",AV13-LOOKUP(2,1/(AI13:AU13<>""),AI13:AU13))) | BJ13: IF(J13="","All_Provinces",IFERROR(VLOOKUP(J13,'09_Lookups'!$A$4:$B$20,2,FALSE),"All_Provinces")) | BK13: IF(K13="","All_Districts",IFERROR(VLOOKUP(K13,'09_Lookups'!$E$4:$F$42,2,FALSE),"All_Districts"))
A14: IF(F14="","",ROW()-3) | B14: AF2-AGF-ALL | C14: Agroforestry saplings and seeds 2026/27 | D14: 11 of 39 | E14: AF2-AGF-N-011 | F14: Agroforestry — Daikundi / Sharistan | G14: Agroforestry saplings / seeds | H14: Saplings and seeds | I14: Emergency Food Security Project (EFSP) – WBK/AF-2 | J14: Central Highland / Bamyan | K14: Daikundi | L14: Sharistan | M14: Saplings: 7000; Seeds kg: 195.5 | N14: World Bank (WBK/AF-2) | O14: Not awarded | P14: 7. Agroforestry Saplings-seeds | T14: IF(AQ14="","",AQ14) | U14: 46142 | V14: 12 | W14: 46478 | X14: IF(W14<>"",W14,IF(OR(T14="",V14=""),"",EDATE(T14,V14))) | AA14: Under Awarding | AB14: The saplings PO has already been issued and PO for seeds is expected to be issued in November 2026 | AC14: IF(F14="","",IF(COUNT(AI14:AV14)=0,IF(AA14="","Not started",AA14),SUBSTITUTE(LOOKUP(2,1/(AI14:AV14<>""),$AI$3:$AV$3),"Date: ",""))) | AD14: IF(OR(F14="",COUNT(AI14:AV14)=0),"",TODAY()-LOOKUP(2,1/(AI14:AV14<>""),AI14:AV14)) | AE14: IF(OR(F14="",COUNT(AI14:AV14)<2),"",LOOKUP(2,1/(AI14:AV14<>""),AI14:AV14)-MIN(AI14:AV14)) | AF14: IF(OR(AD14="",AC14="Not started",AC14=""),"",IFERROR(AD14-IF(VLOOKUP(AC14,'06_Status_Pipeline'!$B$3:$E$20,4,FALSE)="",0,VLOOKUP(AC14,'06_Status_Pipeline'!$B$3:$E$20,4,FALSE)),"")) | AG14: IF(F14="","",IF(OR(AA14="Cancelled",AC14="Cancelled"),"Cancelled",IF(OR(AC14="Completed / Handover",Y14<>"",Z14>=100),"Completed — on track",IF(O14="Not awarded",IF(U14="",IF(X14="","No planned date",IF(TODAY()>X14,"Behind — past planned date",IF(X14-TODAY()<=30,"At risk — close to off track","On track"))),IF(TODAY()>U14,"Behind — award date passed",IF(U14-TODAY()<=30,"At risk — close to off track","On track"))),IF(X14="","No planned date",IF(AND(TODAY()>X14,OR(Z14="",Z14<100)),"Behind — past end date",IF(AND(T14<>"",X14<>"",Z14<>"",(Z14<100),((TODAY()-T14)/MAX(X14-T14,1)*100)-Z14>15),"Behind — progress lag",IF(AND(X14-TODAY()<=30,X14-TODAY()>=0,OR(Z14="",Z14<90)),"At risk — close to off track","On track")))))))) | AH14: IF(OR(F14="",AC14="Completed / Handover",AC14="Cancelled"),"",IF(O14="Not awarded",IF(U14<>"",U14-TODAY(),IF(X14="","",X14-TODAY())),IF(X14="","",X14-TODAY()))) | AW14: IF(OR(F14="",AJ14=""),"",IF(COUNT(AI14:AI14)=0,"",AJ14-LOOKUP(2,1/(AI14:AI14<>""),AI14:AI14))) | AX14: IF(OR(F14="",AK14=""),"",IF(COUNT(AI14:AJ14)=0,"",AK14-LOOKUP(2,1/(AI14:AJ14<>""),AI14:AJ14))) | AY14: IF(OR(F14="",AL14=""),"",IF(COUNT(AI14:AK14)=0,"",AL14-LOOKUP(2,1/(AI14:AK14<>""),AI14:AK14))) | AZ14: IF(OR(F14="",AM14=""),"",IF(COUNT(AI14:AL14)=0,"",AM14-LOOKUP(2,1/(AI14:AL14<>""),AI14:AL14))) | BA14: IF(OR(F14="",AN14=""),"",IF(COUNT(AI14:AM14)=0,"",AN14-LOOKUP(2,1/(AI14:AM14<>""),AI14:AM14))) | BB14: IF(OR(F14="",AO14=""),"",IF(COUNT(AI14:AN14)=0,"",AO14-LOOKUP(2,1/(AI14:AN14<>""),AI14:AN14))) | BC14: IF(OR(F14="",AP14=""),"",IF(COUNT(AI14:AO14)=0,"",AP14-LOOKUP(2,1/(AI14:AO14<>""),AI14:AO14))) | BD14: IF(OR(F14="",AQ14=""),"",IF(COUNT(AI14:AP14)=0,"",AQ14-LOOKUP(2,1/(AI14:AP14<>""),AI14:AP14))) | BE14: IF(OR(F14="",AR14=""),"",IF(COUNT(AI14:AQ14)=0,"",AR14-LOOKUP(2,1/(AI14:AQ14<>""),AI14:AQ14))) | BF14: IF(OR(F14="",AS14=""),"",IF(COUNT(AI14:AR14)=0,"",AS14-LOOKUP(2,1/(AI14:AR14<>""),AI14:AR14))) | BG14: IF(OR(F14="",AT14=""),"",IF(COUNT(AI14:AS14)=0,"",AT14-LOOKUP(2,1/(AI14:AS14<>""),AI14:AS14))) | BH14: IF(OR(F14="",AU14=""),"",IF(COUNT(AI14:AT14)=0,"",AU14-LOOKUP(2,1/(AI14:AT14<>""),AI14:AT14))) | BI14: IF(OR(F14="",AV14=""),"",IF(COUNT(AI14:AU14)=0,"",AV14-LOOKUP(2,1/(AI14:AU14<>""),AI14:AU14))) | BJ14: IF(J14="","All_Provinces",IFERROR(VLOOKUP(J14,'09_Lookups'!$A$4:$B$20,2,FALSE),"All_Provinces")) | BK14: IF(K14="","All_Districts",IFERROR(VLOOKUP(K14,'09_Lookups'!$E$4:$F$42,2,FALSE),"All_Districts"))
