Workbook

Sheet Overview
A1: Six-Month Consistency Plan - Tracker
A2: Day 1: Thursday 01 Oct 2026 | Week 1 starts 05 Oct | Last day: Sunday 04 Apr 2027 | 186 days = 4 launch days + 26 weeks
A4: Direction statement (who I am on 4 Apr 2027) - write 3 sentences:
A9: Accountability person:
A10: Study area for the skill block:
A12: Rule | B12: Counts as done when | C12: Minimum version (still counts)
A13: R1 Move | B13: Do the planned session (strength, Zone 2, Saturday activity or Sunday mobility) on today's row | C13: 15-minute walk
A14: R2 Eat | B14: Protein at every meal, no sugary drinks or packaged snacks, 2.5-3 L water | C14: Protein at 2 meals and the water
A15: R3 Read | B15: 10 pages of non-fiction | C15: 5 pages
A16: R4 Mind | B16: 5-minute journal: today's win, today's lesson, tomorrow's #1 task | C16: One line
A17: R5 Sleep | B17: Screens off 22:15, lights out 23:00, wake 06:30 (+/- 30 min) | C17: Phone charges outside the bedroom
A18: R6 Skill (Mon-Fri) | B18: 60 minutes on the current GIS/RS module, timer on, phone away | C18: 20 minutes
A20: Scoring: 6 rules on weekdays, 5 on weekends. Target 80-90% per week. Below 70% two weeks running: use the minimum versions as the standard for a week. Above 95% three weeks running: raise the bar. A missed day stays missed and the challenge never restarts. Never miss twice in a row. Weekly rule: one commit pushed to the portfolio repo every Friday.
A22: Weeks | B22: Dates | C22: Phase | D22: Nutrition
A23: 0 | B23: 01 Oct - 04 Oct 2026 | C23: Launch | D23: Set up kitchen, first meal prep
A24: 1-2 | B24: 05 Oct - 18 Oct 2026 | C24: Foundation (technique) | D24: Deficit starts: 2,000-2,100 kcal, 140 g protein
A25: 3-8 | B25: 19 Oct - 29 Nov 2026 | C25: Build 1 | D25: Same; 2 planned sweets per week from November
A26: 9 | B26: 30 Nov - 06 Dec 2026 | C26: Deload | D26: Same
A27: 10-12 | B27: 07 Dec - 27 Dec 2026 | C27: Build 2 (holiday stress test) | D27: Hold the minimums through the holidays
A28: 13 | B28: 28 Dec - 03 Jan 2027 | C28: Benchmarks + Cycle 1 review | D28: Checkpoint: waist < 87 cm -> maintenance, else continue deficit
A29: 14-17 | B29: 04 Jan - 31 Jan 2027 | C29: Cycle 2 block A | D29: Per checkpoint
A30: 18-21 | B30: 01 Feb - 28 Feb 2027 | C30: Cycle 2 block B | D30: Per checkpoint
A31: 22 | B31: 01 Mar - 07 Mar 2027 | C31: Deload + diet break | D31: Maintenance for 7 days
A32: 23-25 | B32: 08 Mar - 28 Mar 2027 | C32: Peak | D32: Finish deficit or maintain
A33: 26 | B33: 29 Mar - 04 Apr 2027 | C33: Final benchmarks + review | D33: Decide the next 6 months
... A44: Resting heart rate | B44: measure Day 1 | C44: -3 bpm | D44: -5 to -8 bpm
A46: How to use this workbook
A47: 1. DailyLog: every evening enter 1 or 0 for each rule (R6 only Mon-Fri). Steps, sleep hours and weight are optional. Everything else is computed.
A48: 2. WeeklyReview: on Sunday add weight, waist, energy, the biggest friction and one adjustment. Completion % and status are computed from DailyLog.
A49: 3. Benchmarks: fill the test columns on Day 1-4, then every 4 weeks; the full test battery in weeks 13 and 26.
A50: 4. TrainingPlan / TrainingLog: give TrainingPlan to your trainer; log the key lifts per session in TrainingLog.
A51: 5. SkillPlan: one row per week with the module, focus, resources and the Friday deliverable; mark Done and log hours.
A52: 6. Targets: edit sex, age, weight and activity factor; calorie, protein and water targets recalculate. Meals references those cells.
A53: 7. MonthlyReview: six rows of prompts; the month completion % is computed.
A54: 8. Regenerate a blank copy any time with: python3 build_tracker.py

Sheet Targets
A1: Targets calculator
A2: Yellow cells are inputs. Mifflin-St Jeor BMR x activity factor, minus the deficit; protein and fat per kg bodyweight.
A3: Input | B3: Value | C3: Note
A4: Sex (M/F) | B4: M | C4: Used by the BMR formula
A5: Age (years) | B5: 35 | C5: Edit
A6: Height (cm) | B6: 174
A7: Current weight (kg) | B7: 74 | C7: Update monthly; targets recalculate
A8: Activity factor | B8: 1.45 | C8: 1.2 sedentary, 1.375 light, 1.45 desk job + 4-5 sessions/week + 10k steps, 1.55 moderate
A9: Deficit (fraction) | B9: 0.15 | C9: 0.15 = mild deficit (~300-400 kcal). Use 0 for maintenance (week 22 diet break, or once the waist target is reached)
A10: Protein (g per kg) | B10: 1.8 | C10: 1.6-2.2 g/kg while in a deficit
A11: Fat (g per kg) | B11: 0.8 | C11: 0.7-1.0 g/kg
A13: Output | B13: Value | C13: Note
A14: BMI | B14: =B7/(B6/100)^2 | C14: 18.5-24.9 normal; yours is normal, the issue is fat distribution
A15: BMR (kcal) | B15: =IF(B4="M",10*B7+6.25*B6-5*B5+5,10*B7+6.25*B6-5*B5-161) | C15: Mifflin-St Jeor
A16: Maintenance / TDEE (kcal) | B16: =B15*B8
A17: Calorie target (kcal) | B17: =B16*(1-B9) | C17: Eat within +/- 100 kcal of this on average
A18: Protein target (g) | B18: =B10*B7 | C18: Spread over 4-5 meals
A19: Fat target (g) | B19: =B11*B7
A20: Carbohydrate target (g) | B20: =(B17-4*B18-9*B19)/4 | C20: Mostly at breakfast, pre-gym and dinner
A21: Water target, rest day (L) | B21: =0.035*B7 | C21: 35 ml per kg
A22: Water target, training day (L) | B22: =0.035*B7+0.5 | C22: Rest-day amount + 0.5 L around the session
A23: Waist target (cm) | B23: =0.5*B6 | C23: Waist-to-height ratio below 0.5
A24: Expected loss per week (kg) | B24: =B16*B9*7/7700 | C24: Scale may move slower if muscle is gained; trust the waist

Sheet DailyLog
A1: Day | B1: Date | C1: Weekday | D1: Week | E1: Cycle | F1: Phase | G1: Planned training | H1: Skill module | I1: R1 Move | J1: R2 Eat | K1: R3 Read | L1: R4 Mind | M1: R5 Sleep | N1: R6 Skill | O1: Done | P1: Required | Q1: Logged | R1: Req if logged | S1: Daily % | T1: Steps | U1: Sleep (h) | V1: Weight (kg) | W1: Notes
A2: 1 | B2: 46296 | C2: Thu | D2: 0 | E2: 1 | F2: Launch | G2: Trainer intake + baseline tests (push-ups, dead hang, plank, goblet squat 10RM, resting HR), photos, measurements | H2: Setup | O2: =SUM(I2:M2)+IF(WEEKDAY(B2,2)<=5,N2,0) | P2: =IF(WEEKDAY(B2,2)<=5,6,5) | Q2: =IF(COUNT(I2:N2)>0,1,0) | R2: =P2*Q2 | S2: =IF(Q2=1,O2/P2,"")
A3: 2 | B3: 46297 | C3: Fri | D3: 0 | E3: 1 | F3: Launch | G3: Strength A (technique loads) | H3: Setup | O3: =SUM(I3:M3)+IF(WEEKDAY(B3,2)<=5,N3,0) | P3: =IF(WEEKDAY(B3,2)<=5,6,5) | Q3: =IF(COUNT(I3:N3)>0,1,0) | R3: =P3*Q3 | S3: =IF(Q3=1,O3/P3,"")
A4: 3 | B4: 46298 | C4: Sat | D4: 0 | E4: 1 | F4: Launch | G4: Activity 45-60 min | H4: Setup | O4: =SUM(I4:M4)+IF(WEEKDAY(B4,2)<=5,N4,0) | P4: =IF(WEEKDAY(B4,2)<=5,6,5) | Q4: =IF(COUNT(I4:N4)>0,1,0) | R4: =P4*Q4 | S4: =IF(Q4=1,O4/P4,"")
A5: 4 | B5: 46299 | C5: Sun | D5: 0 | E5: 1 | F5: Launch | G5: Mobility 20 min + finish baseline measurements | H5: Setup | O5: =SUM(I5:M5)+IF(WEEKDAY(B5,2)<=5,N5,0) | P5: =IF(WEEKDAY(B5,2)<=5,6,5) | Q5: =IF(COUNT(I5:N5)>0,1,0) | R5: =P5*Q5 | S5: =IF(Q5=1,O5/P5,"")
A6: 5 | B6: 46300 | C6: Mon | D6: 1 | E6: 1 | F6: Foundation (technique) | G6: Strength A (2 sets, RPE 5-6) | H6: Python for geospatial | O6: =SUM(I6:M6)+IF(WEEKDAY(B6,2)<=5,N6,0) | P6: =IF(WEEKDAY(B6,2)<=5,6,5) | Q6: =IF(COUNT(I6:N6)>0,1,0) | R6: =P6*Q6 | S6: =IF(Q6=1,O6/P6,"")
A7: 6 | B7: 46301 | C7: Tue | D7: 1 | E7: 1 | F7: Foundation (technique) | G7: Zone 2 cardio 30 min | H7: Python for geospatial | O7: =SUM(I7:M7)+IF(WEEKDAY(B7,2)<=5,N7,0) | P7: =IF(WEEKDAY(B7,2)<=5,6,5) | Q7: =IF(COUNT(I7:N7)>0,1,0) | R7: =P7*Q7 | S7: =IF(Q7=1,O7/P7,"")
A8: 7 | B8: 46302 | C8: Wed | D8: 1 | E8: 1 | F8: Foundation (technique) | G8: Strength B (2 sets, RPE 5-6) | H8: Python for geospatial | O8: =SUM(I8:M8)+IF(WEEKDAY(B8,2)<=5,N8,0) | P8: =IF(WEEKDAY(B8,2)<=5,6,5) | Q8: =IF(COUNT(I8:N8)>0,1,0) | R8: =P8*Q8 | S8: =IF(Q8=1,O8/P8,"")
A9: 8 | B9: 46303 | C9: Thu | D9: 1 | E9: 1 | F9: Foundation (technique) | G9: Zone 2 cardio 30 min | H9: Python for geospatial | O9: =SUM(I9:M9)+IF(WEEKDAY(B9,2)<=5,N9,0) | P9: =IF(WEEKDAY(B9,2)<=5,6,5) | Q9: =IF(COUNT(I9:N9)>0,1,0) | R9: =P9*Q9 | S9: =IF(Q9=1,O9/P9,"")
A10: 9 | B10: 46304 | C10: Fri | D10: 1 | E10: 1 | F10: Foundation (technique) | G10: Strength A (2 sets, RPE 5-6) | H10: Python for geospatial | O10: =SUM(I10:M10)+IF(WEEKDAY(B10,2)<=5,N10,0) | P10: =IF(WEEKDAY(B10,2)<=5,6,5) | Q10: =IF(COUNT(I10:N10)>0,1,0) | R10: =P10*Q10 | S10: =IF(Q10=1,O10/P10,"")
A11: 10 | B11: 46305 | C11: Sat | D11: 1 | E11: 1 | F11: Foundation (technique) | G11: Activity 45-60 min (hike, sport, long walk) | H11: Python for geospatial | O11: =SUM(I11:M11)+IF(WEEKDAY(B11,2)<=5,N11,0) | P11: =IF(WEEKDAY(B11,2)<=5,6,5) | Q11: =IF(COUNT(I11:N11)>0,1,0) | R11: =P11*Q11 | S11: =IF(Q11=1,O11/P11,"")
A12: 11 | B12: 46306 | C12: Sun | D12: 1 | E12: 1 | F12: Foundation (technique) | G12: Mobility 20 min + weekly review | H12: Python for geospatial | O12: =SUM(I12:M12)+IF(WEEKDAY(B12,2)<=5,N12,0) | P12: =IF(WEEKDAY(B12,2)<=5,6,5) | Q12: =IF(COUNT(I12:N12)>0,1,0) | R12: =P12*Q12 | S12: =IF(Q12=1,O12/P12,"")
A13: 12 | B13: 46307 | C13: Mon | D13: 2 | E13: 1 | F13: Foundation (technique) | G13: Strength B (2 sets, RPE 5-6) | H13: Python for geospatial | O13: =SUM(I13:M13)+IF(WEEKDAY(B13,2)<=5,N13,0) | P13: =IF(WEEKDAY(B13,2)<=5,6,5) | Q13: =IF(COUNT(I13:N13)>0,1,0) | R13: =P13*Q13 | S13: =IF(Q13=1,O13/P13,"")
... A187: 186 | B187: 46481 | C187: Sun | D187: 26 | E187: 2 | F187: Final benchmarks + review | G187: Final review + measurements + photos + next 6-month plan | H187: Exam + review | O187: =SUM(I187:M187)+IF(WEEKDAY(B187,2)<=5,N187,0) | P187: =IF(WEEKDAY(B187,2)<=5,6,5) | Q187: =IF(COUNT(I187:N187)>0,1,0) | R187: =P187*Q187 | S187: =IF(Q187=1,O187/P187,"")

Sheet WeeklyReview
A1: Weekly review (Sundays, 15 minutes)
A2: Days logged | B2: =SUM(DailyLog!Q2:Q187)
A3: Overall completion to date | B3: =IFERROR(SUM(DailyLog!O2:O187)/SUM(DailyLog!R2:R187),"")
A4: Current week (by today's date) | B4: =IF(TODAY()<DATE(2026,10,5),0,MIN(26,INT((TODAY()-DATE(2026,10,5))/7)+1))
A5: Weeks at or above 80% | B5: =COUNTIF(H8:H34,">=0.8")
A7: Week | B7: Start | C7: End | D7: Cycle | E7: Phase | F7: Done | G7: Required (logged days) | H7: Completion % | I7: Status | J7: Training sessions (R1 ticks) | K7: Skill days (R6 ticks) | L7: Avg sleep (h) | M7: Avg steps | N7: Weight (kg) | O7: Waist (cm) | P7: Friday commit pushed (Y/N) | Q7: Energy (1-5) | R7: Biggest friction | S7: Adjustment for next week
A8: 0 | B8: 46296 | C8: 46299 | D8: 1 | E8: Launch | F8: =SUMIFS(DailyLog!$O$2:$O$187,DailyLog!$D$2:$D$187,$A8) | G8: =SUMIFS(DailyLog!$R$2:$R$187,DailyLog!$D$2:$D$187,$A8) | H8: =IF(G8=0,"",F8/G8) | I8: =IF(H8="","",IF(H8>=0.95,"Raise the bar",IF(H8>=0.8,"On track",IF(H8>=0.7,"Watch","Shrink to minimums")))) | J8: =COUNTIFS(DailyLog!$D$2:$D$187,$A8,DailyLog!$I$2:$I$187,1) | K8: =COUNTIFS(DailyLog!$D$2:$D$187,$A8,DailyLog!$N$2:$N$187,1) | L8: =IFERROR(AVERAGEIFS(DailyLog!$U$2:$U$187,DailyLog!$D$2:$D$187,$A8),"") | M8: =IFERROR(AVERAGEIFS(DailyLog!$T$2:$T$187,DailyLog!$D$2:$D$187,$A8),"")
A9: 1 | B9: 46300 | C9: 46306 | D9: 1 | E9: Foundation (technique) | F9: =SUMIFS(DailyLog!$O$2:$O$187,DailyLog!$D$2:$D$187,$A9) | G9: =SUMIFS(DailyLog!$R$2:$R$187,DailyLog!$D$2:$D$187,$A9) | H9: =IF(G9=0,"",F9/G9) | I9: =IF(H9="","",IF(H9>=0.95,"Raise the bar",IF(H9>=0.8,"On track",IF(H9>=0.7,"Watch","Shrink to minimums")))) | J9: =COUNTIFS(DailyLog!$D$2:$D$187,$A9,DailyLog!$I$2:$I$187,1) | K9: =COUNTIFS(DailyLog!$D$2:$D$187,$A9,DailyLog!$N$2:$N$187,1) | L9: =IFERROR(AVERAGEIFS(DailyLog!$U$2:$U$187,DailyLog!$D$2:$D$187,$A9),"") | M9: =IFERROR(AVERAGEIFS(DailyLog!$T$2:$T$187,DailyLog!$D$2:$D$187,$A9),"")
A10: 2 | B10: 46307 | C10: 46313 | D10: 1 | E10: Foundation (technique) | F10: =SUMIFS(DailyLog!$O$2:$O$187,DailyLog!$D$2:$D$187,$A10) | G10: =SUMIFS(DailyLog!$R$2:$R$187,DailyLog!$D$2:$D$187,$A10) | H10: =IF(G10=0,"",F10/G10) | I10: =IF(H10="","",IF(H10>=0.95,"Raise the bar",IF(H10>=0.8,"On track",IF(H10>=0.7,"Watch","Shrink to minimums")))) | J10: =COUNTIFS(DailyLog!$D$2:$D$187,$A10,DailyLog!$I$2:$I$187,1) | K10: =COUNTIFS(DailyLog!$D$2:$D$187,$A10,DailyLog!$N$2:$N$187,1) | L10: =IFERROR(AVERAGEIFS(DailyLog!$U$2:$U$187,DailyLog!$D$2:$D$187,$A10),"") | M10: =IFERROR(AVERAGEIFS(DailyLog!$T$2:$T$187,DailyLog!$D$2:$D$187,$A10),"")
A11: 3 | B11: 46314 | C11: 46320 | D11: 1 | E11: Build 1 | F11: =SUMIFS(DailyLog!$O$2:$O$187,DailyLog!$D$2:$D$187,$A11) | G11: =SUMIFS(DailyLog!$R$2:$R$187,DailyLog!$D$2:$D$187,$A11) | H11: =IF(G11=0,"",F11/G11) | I11: =IF(H11="","",IF(H11>=0.95,"Raise the bar",IF(H11>=0.8,"On track",IF(H11>=0.7,"Watch","Shrink to minimums")))) | J11: =COUNTIFS(DailyLog!$D$2:$D$187,$A11,DailyLog!$I$2:$I$187,1) | K11: =COUNTIFS(DailyLog!$D$2:$D$187,$A11,DailyLog!$N$2:$N$187,1) | L11: =IFERROR(AVERAGEIFS(DailyLog!$U$2:$U$187,DailyLog!$D$2:$D$187,$A11),"") | M11: =IFERROR(AVERAGEIFS(DailyLog!$T$2:$T$187,DailyLog!$D$2:$D$187,$A11),"")
A12: 4 | B12: 46321 | C12: 46327 | D12: 1 | E12: Build 1 | F12: =SUMIFS(DailyLog!$O$2:$O$187,DailyLog!$D$2:$D$187,$A12) | G12: =SUMIFS(DailyLog!$R$2:$R$187,DailyLog!$D$2:$D$187,$A12) | H12: =IF(G12=0,"",F12/G12) | I12: =IF(H12="","",IF(H12>=0.95,"Raise the bar",IF(H12>=0.8,"On track",IF(H12>=0.7,"Watch","Shrink to minimums")))) | J12: =COUNTIFS(DailyLog!$D$2:$D$187,$A12,DailyLog!$I$2:$I$187,1) | K12: =COUNTIFS(DailyLog!$D$2:$D$187,$A12,DailyLog!$N$2:$N$187,1) | L12: =IFERROR(AVERAGEIFS(DailyLog!$U$2:$U$187,DailyLog!$D$2:$D$187,$A12),"") | M12: =IFERROR(AVERAGEIFS(DailyLog!$T$2:$T$187,DailyLog!$D$2:$D$187,$A12),"")
A13: 5 | B13: 46328 | C13: 46334 | D13: 1 | E13: Build 1 | F13: =SUMIFS(DailyLog!$O$2:$O$187,DailyLog!$D$2:$D$187,$A13) | G13: =SUMIFS(DailyLog!$R$2:$R$187,DailyLog!$D$2:$D$187,$A13) | H13: =IF(G13=0,"",F13/G13) | I13: =IF(H13="","",IF(H13>=0.95,"Raise the bar",IF(H13>=0.8,"On track",IF(H13>=0.7,"Watch","Shrink to minimums")))) | J13: =COUNTIFS(DailyLog!$D$2:$D$187,$A13,DailyLog!$I$2:$I$187,1) | K13: =COUNTIFS(DailyLog!$D$2:$D$187,$A13,DailyLog!$N$2:$N$187,1) | L13: =IFERROR(AVERAGEIFS(DailyLog!$U$2:$U$187,DailyLog!$D$2:$D$187,$A13),"") | M13: =IFERROR(AVERAGEIFS(DailyLog!$T$2:$T$187,DailyLog!$D$2:$D$187,$A13),"")
A14: 6 | B14: 46335 | C14: 46341 | D14: 1 | E14: Build 1 | F14: =SUMIFS(DailyLog!$O$2:$O$187,DailyLog!$D$2:$D$187,$A14) | G14: =SUMIFS(DailyLog!$R$2:$R$187,DailyLog!$D$2:$D$187,$A14) | H14: =IF(G14=0,"",F14/G14) | I14: =IF(H14="","",IF(H14>=0.95,"Raise the bar",IF(H14>=0.8,"On track",IF(H14>=0.7,"Watch","Shrink to minimums")))) | J14: =COUNTIFS(DailyLog!$D$2:$D$187,$A14,DailyLog!$I$2:$I$187,1) | K14: =COUNTIFS(DailyLog!$D$2:$D$187,$A14,DailyLog!$N$2:$N$187,1) | L14: =IFERROR(AVERAGEIFS(DailyLog!$U$2:$U$187,DailyLog!$D$2:$D$187,$A14),"") | M14: =IFERROR(AVERAGEIFS(DailyLog!$T$2:$T$187,DailyLog!$D$2:$D$187,$A14),"")
A15: 7 | B15: 46342 | C15: 46348 | D15: 1 | E15: Build 1 | F15: =SUMIFS(DailyLog!$O$2:$O$187,DailyLog!$D$2:$D$187,$A15) | G15: =SUMIFS(DailyLog!$R$2:$R$187,DailyLog!$D$2:$D$187,$A15) | H15: =IF(G15=0,"",F15/G15) | I15: =IF(H15="","",IF(H15>=0.95,"Raise the bar",IF(H15>=0.8,"On track",IF(H15>=0.7,"Watch","Shrink to minimums")))) | J15: =COUNTIFS(DailyLog!$D$2:$D$187,$A15,DailyLog!$I$2:$I$187,1) | K15: =COUNTIFS(DailyLog!$D$2:$D$187,$A15,DailyLog!$N$2:$N$187,1) | L15: =IFERROR(AVERAGEIFS(DailyLog!$U$2:$U$187,DailyLog!$D$2:$D$187,$A15),"") | M15: =IFERROR(AVERAGEIFS(DailyLog!$T$2:$T$187,DailyLog!$D$2:$D$187,$A15),"")
A16: 8 | B16: 46349 | C16: 46355 | D16: 1 | E16: Build 1 | F16: =SUMIFS(DailyLog!$O$2:$O$187,DailyLog!$D$2:$D$187,$A16) | G16: =SUMIFS(DailyLog!$R$2:$R$187,DailyLog!$D$2:$D$187,$A16) | H16: =IF(G16=0,"",F16/G16) | I16: =IF(H16="","",IF(H16>=0.95,"Raise the bar",IF(H16>=0.8,"On track",IF(H16>=0.7,"Watch","Shrink to minimums")))) | J16: =COUNTIFS(DailyLog!$D$2:$D$187,$A16,DailyLog!$I$2:$I$187,1) | K16: =COUNTIFS(DailyLog!$D$2:$D$187,$A16,DailyLog!$N$2:$N$187,1) | L16: =IFERROR(AVERAGEIFS(DailyLog!$U$2:$U$187,DailyLog!$D$2:$D$187,$A16),"") | M16: =IFERROR(AVERAGEIFS(DailyLog!$T$2:$T$187,DailyLog!$D$2:$D$187,$A16),"")
A17: 9 | B17: 46356 | C17: 46362 | D17: 1 | E17: Deload | F17: =SUMIFS(DailyLog!$O$2:$O$187,DailyLog!$D$2:$D$187,$A17) | G17: =SUMIFS(DailyLog!$R$2:$R$187,DailyLog!$D$2:$D$187,$A17) | H17: =IF(G17=0,"",F17/G17) | I17: =IF(H17="","",IF(H17>=0.95,"Raise the bar",IF(H17>=0.8,"On track",IF(H17>=0.7,"Watch","Shrink to minimums")))) | J17: =COUNTIFS(DailyLog!$D$2:$D$187,$A17,DailyLog!$I$2:$I$187,1) | K17: =COUNTIFS(DailyLog!$D$2:$D$187,$A17,DailyLog!$N$2:$N$187,1) | L17: =IFERROR(AVERAGEIFS(DailyLog!$U$2:$U$187,DailyLog!$D$2:$D$187,$A17),"") | M17: =IFERROR(AVERAGEIFS(DailyLog!$T$2:$T$187,DailyLog!$D$2:$D$187,$A17),"")
A18: 10 | B18: 46363 | C18: 46369 | D18: 1 | E18: Build 2 (holiday stress test) | F18: =SUMIFS(DailyLog!$O$2:$O$187,DailyLog!$D$2:$D$187,$A18) | G18: =SUMIFS(DailyLog!$R$2:$R$187,DailyLog!$D$2:$D$187,$A18) | H18: =IF(G18=0,"",F18/G18) | I18: =IF(H18="","",IF(H18>=0.95,"Raise the bar",IF(H18>=0.8,"On track",IF(H18>=0.7,"Watch","Shrink to minimums")))) | J18: =COUNTIFS(DailyLog!$D$2:$D$187,$A18,DailyLog!$I$2:$I$187,1) | K18: =COUNTIFS(DailyLog!$D$2:$D$187,$A18,DailyLog!$N$2:$N$187,1) | L18: =IFERROR(AVERAGEIFS(DailyLog!$U$2:$U$187,DailyLog!$D$2:$D$187,$A18),"") | M18: =IFERROR(AVERAGEIFS(DailyLog!$T$2:$T$187,DailyLog!$D$2:$D$187,$A18),"")
A19: 11 | B19: 46370 | C19: 46376 | D19: 1 | E19: Build 2 (holiday stress test) | F19: =SUMIFS(DailyLog!$O$2:$O$187,DailyLog!$D$2:$D$187,$A19) | G19: =SUMIFS(DailyLog!$R$2:$R$187,DailyLog!$D$2:$D$187,$A19) | H19: =IF(G19=0,"",F19/G19) | I19: =IF(H19="","",IF(H19>=0.95,"Raise the bar",IF(H19>=0.8,"On track",IF(H19>=0.7,"Watch","Shrink to minimums")))) | J19: =COUNTIFS(DailyLog!$D$2:$D$187,$A19,DailyLog!$I$2:$I$187,1) | K19: =COUNTIFS(DailyLog!$D$2:$D$187,$A19,DailyLog!$N$2:$N$187,1) | L19: =IFERROR(AVERAGEIFS(DailyLog!$U$2:$U$187,DailyLog!$D$2:$D$187,$A19),"") | M19: =IFERROR(AVERAGEIFS(DailyLog!$T$2:$T$187,DailyLog!$D$2:$D$187,$A19),"")
... A34: 26 | B34: 46475 | C34: 46481 | D34: 2 | E34: Final benchmarks + review | F34: =SUMIFS(DailyLog!$O$2:$O$187,DailyLog!$D$2:$D$187,$A34) | G34: =SUMIFS(DailyLog!$R$2:$R$187,DailyLog!$D$2:$D$187,$A34) | H34: =IF(G34=0,"",F34/G34) | I34: =IF(H34="","",IF(H34>=0.95,"Raise the bar",IF(H34>=0.8,"On track",IF(H34>=0.7,"Watch","Shrink to minimums")))) | J34: =COUNTIFS(DailyLog!$D$2:$D$187,$A34,DailyLog!$I$2:$I$187,1) | K34: =COUNTIFS(DailyLog!$D$2:$D$187,$A34,DailyLog!$N$2:$N$187,1) | L34: =IFERROR(AVERAGEIFS(DailyLog!$U$2:$U$187,DailyLog!$D$2:$D$187,$A34),"") | M34: =IFERROR(AVERAGEIFS(DailyLog!$T$2:$T$187,DailyLog!$D$2:$D$187,$A34),"")

Sheet Benchmarks
A1: Benchmarks and measurements
A2: Same conditions each time: morning, before breakfast, waist relaxed at the navel. Photos front/side/back in the same light and clothing.
A4: Metric | B4: Unit | C4: Day 1-4 (1-4 Oct) | D4: Wk 4 (1 Nov) | E4: Wk 8 (29 Nov) | F4: Wk 13 (3 Jan) | G4: Wk 17 (31 Jan) | H4: Wk 21 (28 Feb) | I4: Wk 26 (4 Apr) | J4: Target Wk 26 | K4: Change (Wk 26 - Day 1)
A5: Body weight | B5: kg | J5: 67-70 | K5: =IF(OR(C5="",I5=""),"",I5-C5)
A6: Waist at navel | B6: cm | J6: -8 to -10 and < 87 | K6: =IF(OR(C6="",I6=""),"",I6-C6)
A7: Chest | B7: cm | J7: - | K7: =IF(OR(C7="",I7=""),"",I7-C7)
A8: Hips | B8: cm | J8: - | K8: =IF(OR(C8="",I8=""),"",I8-C8)
A9: Resting heart rate | B9: bpm | J9: -5 to -8 | K9: =IF(OR(C9="",I9=""),"",I9-C9)
A10: Push-ups to failure | B10: reps | J10: +15 (min 25) | K10: =IF(OR(C10="",I10=""),"",I10-C10)
A11: Dead hang | B11: s | J11: 60-90 | K11: =IF(OR(C11="",I11=""),"",I11-C11)
A12: Plank | B12: s | J12: 90+ | K12: =IF(OR(C12="",I12=""),"",I12-C12)
A13: Strict chin-ups | B13: reps | J13: 5 | K13: =IF(OR(C13="",I13=""),"",I13-C13)
A14: Goblet squat 10RM (Day 1 only) | B14: kg | J14: - | K14: =IF(OR(C14="",I14=""),"",I14-C14)
A15: Back squat 5RM | B15: kg | J15: ~70 (1.0 x BW) | K15: =IF(OR(C15="",I15=""),"",I15-C15)
A16: Deadlift 5RM | B16: kg | J16: ~90 (1.25 x BW) | K16: =IF(OR(C16="",I16=""),"",I16-C16)
... A22: Skill deliverables shipped (cumulative) | B22: count | J22: 26 | K22: =IF(OR(C22="",I22=""),"",I22-C22)
A23: Photos taken (Y/N) | B23: Y/N | J23: Y

Sheet TrainingPlan
A1: Training programme (proposal for the trainer)
A2: Structure, progression and grip strategy are what matter; the trainer chooses exact exercises and loads.
A4: Cycle 1 (Weeks 1-13): three full-body sessions Mon/Wed/Fri, alternating A/B (W1 = A,B,A; W2 = B,A,B ...). Warm-up 8 min: bike/rower, wrist circles + light wrist flexion/extension, band pull-aparts, 10 bodyweight squats.
A6: Session A
A7: Slot | B7: Weeks 1-4 | C7: Weeks 5-13 | D7: Sets x reps | E7: Notes
A8: Squat pattern | B8: Goblet squat | C8: Barbell back squat (or leg press) | D8: 3 x 8-12 | E8: Main lower-body driver
A9: Horizontal push | B9: Dumbbell bench press, neutral grip | C9: Barbell bench from week 9 if wrists are comfortable; stacked wrists | D9: 3 x 8-12 | E9: Neutral grip protects small wrists early
A10: Hip hinge | B10: Dumbbell Romanian deadlift | C10: Barbell RDL or trap-bar deadlift; straps allowed from week 8 | D10: 3 x 8-12 | E10: Grip must never limit the hinge
A11: Horizontal pull | B11: Chest-supported dumbbell row | C11: Seated cable row | D11: 3 x 10-12 | E11: Posture
A12: Core | B12: Plank | C12: Long-lever or weighted plank | D12: 3 x 30-60 s
A13: Grip finisher | B13: Farmer carry | C13: Farmer carry, heavier | D13: 3 x 30-40 m | E13: Forearm size is what changes the look of a small wrist
A15: Session B
A16: Slot | B16: Weeks 1-4 | C16: Weeks 5-13 | D16: Sets x reps | E16: Notes
A17: Single-leg | B17: Split squat or walking lunge | C17: Bulgarian split squat | D17: 3 x 8-10 / leg
A18: Vertical pull | B18: Lat pulldown | C18: Assisted chin-up, aim at the first strict rep by week 13 | D18: 3 x 8-12
A19: Vertical push | B19: Seated dumbbell shoulder press, neutral grip | C19: Same, heavier | D19: 3 x 8-12
A20: Glute / hamstring | B20: Glute bridge | C20: Hip thrust or 45-degree back extension | D20: 3 x 10-12
A21: Upper back / posture | B21: Face pull | C21: Face pull or rear-delt fly | D21: 3 x 12-15 | E21: Counteracts desk posture
A22: Core | B22: Side plank | C22: Pallof press | D22: 3 x 30 s / 10 reps
A23: Grip finisher | B23: Dead hang | C23: Dead hang, target 60 s by week 13 | D23: 3 x max time
A25: Loading rules, cardio, steps
A26: Weeks | B26: Rule
A27: 1-2 | B27: 2 sets per exercise, RPE 5-6 (4-5 reps in reserve). Technique and habit.
A28: 3-8 | B28: 3 sets, RPE 7-8. Double progression: top of the rep range on all sets -> +2.5 kg upper / +5 kg lower, restart at the bottom of the range.
A29: 9 | B29: Deload: 2 sets, 40% less load, same movements.
A30: 10-12 | B30: 3-4 sets; main lifts 6-10 reps at RPE 8; accessories 10-15.
A31: 13 | B31: Benchmarks. Mon: back squat 5RM, bench 5RM, push-ups. Wed: deadlift 5RM, chin-ups, dead hang, plank. Fri: light full body + 12-min Cooper test. Sun: measurements, photos, review.
A32: Tue/Thu | B32: Zone 2 cardio (talk test, ~60-70% HRmax): 30 min weeks 1-4, 35-40 min from week 5. Incline treadmill, bike, rower or elliptical.
A33: Sat | B33: 45-60 min of an activity you enjoy.
A34: Sun | B34: 20 min mobility (hips, thoracic spine, shoulders, wrists).
A35: Steps | B35: 8,000/day weeks 0-4, 10,000/day from week 5 (15-min walks after lunch and dinner).
A37: Wrist and grip strategy
A38: # | B38: Rule
A39: 1 | B39: Neutral-grip dumbbells for pressing in weeks 1-4; barbells only when wrists feel stable, knuckles stacked over the forearm.
A40: 2 | B40: Wrist warm-up every session; wrist wraps only for heavy pressing if there is discomfort.
A41: 3 | B41: Two grip finishers per week (farmer carry, dead hang).
A42: 4 | B42: Lifting straps from week 8 on RDL, deadlift and heavy rows so grip fatigue never limits leg and back development.
A44: Cycle 2 (Weeks 14-26): four-day upper/lower split. Mon Lower A, Tue Upper A, Wed Zone 2 40 min, Thu Lower B, Fri Upper B, Sat intervals (8 x 1 min hard / 2 min easy) or sport, Sun mobility.
A46: Session | B46: Exercises (sets x reps)
A47: Lower A | B47: Back squat 4 x 5-8; Romanian deadlift 3 x 8-10; leg press or split squat 3 x 10-12; calf raise 3 x 12-15; hanging knee raise 3 x 10
...

Sheet TrainingLog
A1: Date | B1: Weekday | C1: Week | D1: Planned session | E1: Done (1/0) | F1: Duration (min) | G1: Lift 1 (exercise: kg x reps) | H1: Lift 2 | I1: Lift 3 | J1: RPE (1-10) | K1: Notes
A2: 46296 | B2: Thu | C2: 0 | D2: Trainer intake + baseline tests (push-ups, dead hang, plank, goblet squat 10RM, resting HR), photos, measurements
A3: 46297 | B3: Fri | C3: 0 | D3: Strength A (technique loads)
A4: 46298 | B4: Sat | C4: 0 | D4: Activity 45-60 min
A5: 46299 | B5: Sun | C5: 0 | D5: Mobility 20 min + finish baseline measurements
A6: 46300 | B6: Mon | C6: 1 | D6: Strength A (2 sets, RPE 5-6)
A7: 46301 | B7: Tue | C7: 1 | D7: Zone 2 cardio 30 min
A8: 46302 | B8: Wed | C8: 1 | D8: Strength B (2 sets, RPE 5-6)
A9: 46303 | B9: Thu | C9: 1 | D9: Zone 2 cardio 30 min
A10: 46304 | B10: Fri | C10: 1 | D10: Strength A (2 sets, RPE 5-6)
A11: 46305 | B11: Sat | C11: 1 | D11: Activity 45-60 min (hike, sport, long walk)
A12: 46306 | B12: Sun | C12: 1 | D12: Mobility 20 min + weekly review
A13: 46307 | B13: Mon | C13: 2 | D13: Strength B (2 sets, RPE 5-6)
... A187: 46481 | B187: Sun | C187: 26 | D187: Final review + measurements + photos + next 6-month plan

Sheet SkillPlan
A1: Skill block: GIS and remote sensing
A2: 60 min Mon-Fri (20:45-21:45), optional 90 min Saturday project session, one commit pushed every Friday. One study area for all modules.
A4: Week | B4: Dates | C4: Module | D4: Focus this week | E4: Resources (free unless noted) | F4: Friday deliverable | G4: Done (Y/N) | H4: Hours logged | I4: Notes / link
A5: 0 | B5: 01 Oct - 04 Oct | C5: Setup | D5: Install Miniforge/conda env (geopandas, rasterio, rioxarray, xarray, rasterstats, matplotlib, jupyterlab, scikit-learn, earthengine-api, geemap), VS Code, Git. Create the public portfolio repo. Register for Google Earth Engine (approval can take days). Choose the study area and download admin boundaries, roads, DEM. | E5: Miniforge docs; GitHub; earthengine.google.com | F5: Portfolio repo with README: study area + 26-week plan
A6: 1 | B6: 05 Oct - 11 Oct | C6: Python for geospatial | D6: Python and pandas refresh: types, functions, DataFrames, reading CSV, plotting. | E6: Spatial Thoughts - Python Foundation for Spatial Analysis (part 1) | F6: Notebook 01: pandas analysis of an attribute table exported from ArcGIS Pro
A7: 2 | B7: 12 Oct - 18 Oct | C7: Python for geospatial | D7: GeoPandas vectors: read shapefile/GDB, CRS and reprojection (EPSG:4326 vs UTM), buffer, overlay, spatial join, dissolve. | E7: Spatial Thoughts - Python Foundation (GeoPandas); GeoPandas docs | F7: Notebook 02: vector analysis of the study area (buffers + spatial join) with a map
A8: 3 | B8: 19 Oct - 25 Oct | C8: Python for geospatial | D8: Rasters with rasterio/rioxarray: open DEM, reproject, clip to boundary, slope and hillshade with numpy, zonal statistics (rasterstats). | E8: Rasterio and rioxarray docs; rasterstats docs | F8: Notebook 03: terrain statistics per district
A9: 4 | B9: 26 Oct - 01 Nov | C9: Python for geospatial | D9: Integration project: reproduce one ArcGIS Pro Day-1 exercise end to end (buffers, overlay, zonal stats), export to GeoPackage, write README. | E9: Own course material | F9: Project 1 folder: README, figures, GeoPackage
A10: 5 | B10: 02 Nov - 08 Nov | C10: Google Earth Engine | D10: Code Editor, Image and ImageCollection, filters, Sentinel-2 cloud masking (SCL / Cloud Score+), median composites, visualisation. | E10: Spatial Thoughts - End-to-End GEE (modules 1-2); EEFA open-access book F1 | F10: Script 01: cloud-free Sentinel-2 composite of the study area
A11: 6 | B11: 09 Nov - 15 Nov | C11: Google Earth Engine | D11: Reducers and indices: NDVI/NDWI/NDBI, zonal statistics by admin unit (reduceRegions), exports to Drive/Assets. | E11: End-to-End GEE (modules 2-3); EEFA F2-F3 | F11: Script 02: mean NDVI per district table + map export
A12: 7 | B12: 16 Nov - 22 Nov | C12: Google Earth Engine | D12: Time series: monthly NDVI 2019-2026, charts (ui.Chart), simple anomalies, GEE Apps basics. | E12: End-to-End GEE (modules 3-4); EEFA F4 | F12: NDVI time-series chart + a published GEE App
A13: 8 | B13: 23 Nov - 29 Nov | C13: Google Earth Engine | D13: GEE Python API and geemap: authenticate, replicate the scripts in Jupyter, interactive maps, export GeoTIFF. | E13: End-to-End GEE (Python module); geemap docs | F13: Notebook 04: GEE composites and time series in Python
A14: 9 | B14: 30 Nov - 06 Dec | C14: RS analytics (deload week: theory) | D14: Supervised vs unsupervised classification, spectral signatures, training-sample design, Random Forest, accuracy metrics. | E14: EEFA F2.1-F2.2; NASA ARSET - Using GEE for Land Monitoring (part 1) | F14: One-page methods note + training sample scheme (5-6 classes)
A15: 10 | B15: 07 Dec - 13 Dec | C15: RS analytics | D15: Random Forest classification in GEE: collect training samples, train, classify the Sentinel-2 composite, visualise. | E15: EEFA F2.1; End-to-End GEE supervised classification | F15: Land-cover map v1 of the study area
A16: 11 | B16: 14 Dec - 20 Dec | C16: RS analytics | D16: Accuracy assessment: stratified random validation points, confusion matrix, overall/producer/user accuracy, F1; add features (indices, texture, DEM) and iterate. | E16: EEFA F2.2; ARSET GEE part 2 (classification and accuracy) | F16: Accuracy report + land-cover map v2 (target >= 85% OA)
... A31: 26 | B31: 29 Mar - 04 Apr | C31: Exam + review | D31: Sit the exam; portfolio review; write the next six-month skill plan. | E31: - | F31: Exam taken; next plan committed
A33: Certification: primary Esri ArcGIS Pro Associate 2025 (75 questions, 90 min; aimed at 2-4 years of experience) or ArcGIS Pro Professional 2025 if you have more than 4 years. Stretch option matching the new skills: ArcGIS API for Python Associate 2026. Buy the voucher and book the date in week 20. Optional paid cohort: Spatial Thoughts live 'Python Foundation for Spatial Analysis', 21-22 and 28-29 Oct 2026 (aligns with weeks 3-4). NASA ARSET trainings are free: join any GEE or land-cover session scheduled Oct-Mar.
D35: Key free resources
D36: Resource | E36: URL
D37: Spatial Thoughts OpenCourseWare (Python Foundation, End-to-End GEE, Mapping and Data Visualization with Python, Cloud Native Remote Sensing with Python) | E37: https://courses.spatialthoughts.com/
D38: Cloud-Based Remote Sensing with Google Earth Engine: Fundamentals and Applications (open access) | E38: https://link.springer.com/book/10.1007/978-3-031-26588-4
D39: NASA ARSET - Using Google Earth Engine for Land Monitoring Applications | E39: https://www.earthdata.nasa.gov/learn/trainings/using-google-earth-engine-land-monitoring-applications
D40: NASA ARSET training catalogue | E40: https://www.earthdata.nasa.gov/learn/trainings
D41: Introduction to PostGIS workshop | E41: https://postgis.net/workshops/postgis-intro/
D42: GeoPandas documentation | E42: https://geopandas.org/
D43: Rasterio documentation | E43: https://rasterio.readthedocs.io/
D44: geemap documentation | E44: https://geemap.org/
D45: Esri Technical Certification (exam list, learning plans) | E45: https://www.esri.com/training/certification/

Sheet Meals
A1: Meal framework
A2: Numbers come from the Targets sheet. Protein first on every plate; oil measured with a spoon; no liquid calories.
A4: Live targets
A5: Target | B5: Value | C5: Note
A6: Calories (kcal) | B6: =Targets!B17 | C6: Weeks 0-13 deficit. Week 13 checkpoint: waist < 87 cm -> set deficit to 0 on Targets. Week 22: deficit 0 for 7 days.
A7: Protein (g) | B7: =Targets!B18 | C7: 130-150 g; spread over 4-5 meals
A8: Fat (g) | B8: =Targets!B19
A9: Carbohydrate (g) | B9: =Targets!B20 | C9: Breakfast, pre-gym, dinner
A10: Water, training day (L) | B10: =Targets!B22 | C10: 500 ml on waking, 500 ml pre-gym, 500-750 ml during training; rest days 0.5 L less
A11: Fibre (g) | B11: 30 | C11: Vegetables, legumes, oats, fruit
A12: Sugary drinks / juice | B12: 0 | C12: Fastest belly-fat lever
A13: Alcohol | B13: None or social only | C13: Decide before Day 1
A14: Sweets | B14: 0 in Oct; 2 planned/week from Nov | C14: Planned treats are not misses
A15: Expected rate | B15: 0.3-0.5 kg/week; waist ~1 cm / 2 weeks | C15: Slower on the scale if muscle is gained
A17: Daily template: base 2,150 kcal / 145 g protein; the optional 21:30 snack adds 150 kcal / 15 g. To land near the calorie target, skip the optional snack and halve the lunch starch.
A18: Time | B18: Meal | C18: Example | D18: kcal | E18: Protein (g)
A19: 06:45 | B19: Breakfast | C19: 3 eggs or 250 g strained yogurt; 60 g oats or 2 slices wholegrain bread; 1 fruit; tea/coffee without sugar | D19: 500 | E19: 35
A20: 10:30 | B20: Snack | C20: 200 g yogurt, or 30 g nuts + fruit, or 2 boiled eggs | D20: 200 | E20: 15
A21: 12:30 | B21: Lunch (packed) | C21: 150 g cooked chicken/fish/lean meat or 200 g legumes; 1 cup cooked rice/bulgur or 2 flatbreads; large salad or cooked vegetables; 1 tbsp olive oil | D21: 600 | E21: 40
A22: 16:30 | B22: Pre-gym | C22: Banana + 3 dates, or bread with cheese/peanut butter; 500 ml water | D22: 250 | E22: 10
A23: 18:00-19:15 | B23: Gym | C23: 500-750 ml water | D23: 0 | E23: 0
A24: 19:45 | B24: Dinner | C24: 150-200 g protein source; 2 cups vegetables; one fist of potatoes or rice; 1 tbsp oil | D24: 600 | E24: 45
A25: 21:30 (optional) | B25: If hungry | C25: Cottage cheese, yogurt or a protein shake; kitchen closed at 22:00 | D25: 150 | E25: 15
B26: Total, base (without optional snack) | D26: =SUM(D19:D24) | E26: =SUM(E19:E24)
B27: Total with optional snack | D27: =SUM(D19:D25) | E27: =SUM(E19:E25)
A29: Rules
A30: # | B30: Rule
A31: 1 | B31: Protein first on every plate; vegetables at lunch and dinner; oil measured with a spoon.
A32: 2 | B32: Eat out at most twice a week; order protein plus vegetables first; the rest is 80/20.
A33: 3 | B33: Sunday prep (60 min): cook 1 kg chicken or legumes, 4 cups rice, chop vegetables for 4 days, boil 8 eggs, portion 5 lunches.
A34: 4 | B34: Adjust every 2 weeks, not every day: if weight and waist have not moved in 14 days, remove 150 kcal (the dinner starch) or add 1,500 steps. One change at a time.
A35: 5 | B35: Week 13 checkpoint: waist below 87 cm -> maintenance (deficit 0 on Targets) and train for muscle; otherwise continue the deficit.
A36: 6 | B36: Week 22: 7-day diet break at maintenance, deliberately, together with the training deload.
A37: 7 | B37: Sleep 7-8 h. Short sleep raises appetite and stores fat around the waist.
A39: Sunday prep checklist
B40: Item | C40: Done
B41: 1 kg chicken / fish / legumes cooked
B42: 4 cups rice or bulgur cooked
B43: Vegetables chopped for 4 days
B44: 8 eggs boiled
...

Sheet MonthlyReview
A1: Monthly review (30 min) and cycle reviews (60 min)
A2: Month completion % is computed from DailyLog. Read the whole plan before the Week 13 and Week 26 reviews; do not revise from memory.
A4: Month | B4: From | C4: Review date (Sunday) | D4: Completion % | E4: What worked | F4: What broke | G4: Which metrics moved (waist, weight, lifts, skill) | H4: One change for next month | I4: Rules to simplify or drop | J4: Measurements + photos done (Y/N)
A5: M1 | B5: 46296 | C5: 46327 | D5: =IFERROR(SUMIFS(DailyLog!$O$2:$O$187,DailyLog!$B$2:$B$187,">="&B5,DailyLog!$B$2:$B$187,"<="&C5)/SUMIFS(DailyLog!$R$2:$R$187,DailyLog!$B$2:$B$187,">="&B5,DailyLog!$B$2:$B$187,"<="&C5),"")
A6: M2 | B6: 46328 | C6: 46355 | D6: =IFERROR(SUMIFS(DailyLog!$O$2:$O$187,DailyLog!$B$2:$B$187,">="&B6,DailyLog!$B$2:$B$187,"<="&C6)/SUMIFS(DailyLog!$R$2:$R$187,DailyLog!$B$2:$B$187,">="&B6,DailyLog!$B$2:$B$187,"<="&C6),"")
A7: M3 (Cycle 1 review) | B7: 46356 | C7: 46390 | D7: =IFERROR(SUMIFS(DailyLog!$O$2:$O$187,DailyLog!$B$2:$B$187,">="&B7,DailyLog!$B$2:$B$187,"<="&C7)/SUMIFS(DailyLog!$R$2:$R$187,DailyLog!$B$2:$B$187,">="&B7,DailyLog!$B$2:$B$187,"<="&C7),"")
A8: M4 | B8: 46391 | C8: 46418 | D8: =IFERROR(SUMIFS(DailyLog!$O$2:$O$187,DailyLog!$B$2:$B$187,">="&B8,DailyLog!$B$2:$B$187,"<="&C8)/SUMIFS(DailyLog!$R$2:$R$187,DailyLog!$B$2:$B$187,">="&B8,DailyLog!$B$2:$B$187,"<="&C8),"")
A9: M5 | B9: 46419 | C9: 46446 | D9: =IFERROR(SUMIFS(DailyLog!$O$2:$O$187,DailyLog!$B$2:$B$187,">="&B9,DailyLog!$B$2:$B$187,"<="&C9)/SUMIFS(DailyLog!$R$2:$R$187,DailyLog!$B$2:$B$187,">="&B9,DailyLog!$B$2:$B$187,"<="&C9),"")
A10: M6 (final review) | B10: 46447 | C10: 46481 | D10: =IFERROR(SUMIFS(DailyLog!$O$2:$O$187,DailyLog!$B$2:$B$187,">="&B10,DailyLog!$B$2:$B$187,"<="&C10)/SUMIFS(DailyLog!$R$2:$R$187,DailyLog!$B$2:$B$187,">="&B10,DailyLog!$B$2:$B$187,"<="&C10),"")
A12: Cycle review questions (Week 13 and Week 26)
A13: 1. Do I have the time and energy for each rule as written? If not, what is the baseline version?
A14: 2. Am I getting results that match the effort? If effort is high and results are flat, change the approach, not the goal.
A15: 3. Does each rule still fit my life and values? Keep, simplify or drop.
A16: 4. What evidence of progress do I have (waist, lifts, deliverables, books)? Compare to Day 1, not to the ideal.
A17: 5. Nutrition checkpoint: is the waist below 87 cm? If yes, set the deficit to 0 and train for muscle.
A18: 6. Skill: what is public in the portfolio? What is the next deliverable that would matter to an employer or client?
A19: 7. What is the one bold move for the next 13 weeks?
